Workbook

Sheet 01-说明与查询
A1: 双中心能碳管控平台 · 基础参数与指标字典
A2: 依据《“双中心”项目能碳管控指标体系（9.16）V1.7》提炼 · 用于交付开发阶段的参数与数据说明速查
A3: 版本 V1.0 | 生成日期 2026-09-18 | 指标 94 项 | 原子参数 97 项 | 变量映射 284 行
A5: ① 快速查询 — 在 B6 输入或下拉选择「编码 / 名称」，下方自动返回该参数或指标的全部说明信息
A6: 查询键（编码或名称） | B6: EN-013 | C6: 查询状态 | D6: =IF($B$6="","请输入查询键（编码或名称）",IF($B$7="","未找到匹配记录，请检查编码或名称","匹配成功")) -> 匹配成功
A7: 匹配行号（辅助） | B7: =IF($B$6="","",IFERROR(MATCH($B$6,'02-基础参数表'!$B:$B,0),IFERROR(MATCH($B$6,'02-基础参数表'!$C:$C,0),""))) -> 28 | D7: 在 WPS / Excel 中修改 B6 后会自动重算；单元格内已预置示例（EN-013 综合能源消费量）的缓存结果。
A8: 编码 | B8: =IF(OR($B$6="",$B$7=""),"",INDEX('02-基础参数表'!$A:$U,$B$7,2)) -> EN-013
A9: 名称 | B9: =IF(OR($B$6="",$B$7=""),"",INDEX('02-基础参数表'!$A:$U,$B$7,3)) -> 综合能源消费量
A10: 类型（参数 / 指标） | B10: =IF(OR($B$6="",$B$7=""),"",INDEX('02-基础参数表'!$A:$U,$B$7,4)) -> 参数
A11: 符号 | B11: =IF(OR($B$6="",$B$7=""),"",INDEX('02-基础参数表'!$A:$U,$B$7,5)) -> E
A12: 参数类别 | B12: =IF(OR($B$6="",$B$7=""),"",INDEX('02-基础参数表'!$A:$U,$B$7,6)) -> 能源数据
A13: 数据说明 | B13: =IF(OR($B$6="",$B$7=""),"",INDEX('02-基础参数表'!$A:$U,$B$7,7)) -> 统计期内组织综合能源消费总量，由各能源品种消耗量 × 折标准煤系数加总得到；电力按当量值折标
A14: 单位 | B14: =IF(OR($B$6="",$B$7=""),"",INDEX('02-基础参数表'!$A:$U,$B$7,8)) -> tce
A15: 数据格式 | B15: =IF(OR($B$6="",$B$7=""),"",INDEX('02-基础参数表'!$A:$U,$B$7,9)) -> 数值（3 位小数）
A16: 小数位 | B16: =IF(OR($B$6="",$B$7=""),"",INDEX('02-基础参数表'!$A:$U,$B$7,10)) -> 3
A17: 取值范围 / 枚举 | B17: =IF(OR($B$6="",$B$7=""),"",INDEX('02-基础参数表'!$A:$U,$B$7,11)) -> ≥0
A18: 默认取值 / 参考值 | B18: =IF(OR($B$6="",$B$7=""),"",INDEX('02-基础参数表'!$A:$U,$B$7,12)) -> —
A19: 数据来源 | B19: =IF(OR($B$6="",$B$7=""),"",INDEX('02-基础参数表'!$A:$U,$B$7,13)) -> 集控中心（系统自动计算）
A20: 来源对象 / 字段 | B20: =IF(OR($B$6="",$B$7=""),"",INDEX('02-基础参数表'!$A:$U,$B$7,14)) -> 计算字段
A21: 获取方式 | B21: =IF(OR($B$6="",$B$7=""),"",INDEX('02-基础参数表'!$A:$U,$B$7,15)) -> 计算
A22: 更新频率 | B22: =IF(OR($B$6="",$B$7=""),"",INDEX('02-基础参数表'!$A:$U,$B$7,16)) -> 月度
A23: 是否必填 | B23: =IF(OR($B$6="",$B$7=""),"",INDEX('02-基础参数表'!$A:$U,$B$7,17)) -> 是
A24: 责任单位 | B24: =IF(OR($B$6="",$B$7=""),"",INDEX('02-基础参数表'!$A:$U,$B$7,18)) -> 电装（统一计算）
A25: 关联编码 | B25: =IF(OR($B$6="",$B$7=""),"",INDEX('02-基础参数表'!$A:$U,$B$7,19)) -> IND-003、IND-005、IND-008、IND-010、IND-012
A26: 校验规则 | B26: =IF(OR($B$6="",$B$7=""),"",INDEX('02-基础参数表'!$A:$U,$B$7,20)) -> ≥0
A27: 备注 | B27: =IF(OR($B$6="",$B$7=""),"",INDEX('02-基础参数表'!$A:$U,$B$7,21)) -> 电力折标使用当量值系数 FAC-001
A30: ② 工作表说明
A31: 工作表 | B31: 内容 | C31: 主要用途 | D31: 条目数
A32: 01-说明与查询 | B32: 工作簿说明、快速查询区、编码规则、常用查询公式示例 | D32: 1
A33: 02-基础参数表 | B33: 参数与指标的统一定义表（含来源、格式、校验、责任单位） | C33: 公式驱动速查的主表，支持按类型 / 类别筛选 | D33: 191 项
A34: 03-指标清单 | B34: 94 项指标的原始定义、计算公式、层级、类别、来源、用途、覆盖范围、实施要求 | C34: 保留指标体系原文信息，供需求与验收对照 | D34: 94 项
A35: 04-公式变量映射 | B35: 指标公式中的每个变量 ↔ 基础参数表条目 | C35: 支撑公式自动取数、口径核对与影响分析 | D35: 284 行
A36: 05-数据源清单 | B36: 各数据源系统、归属方、提供内容、对接方式、责任方 | C36: 接口与取数方案的设计依据 | D36: 10 项
A37: 06-枚举字典 | B37: 组织、产线、工序、能源品种、格式、频率等全部枚举值域 | C37: 字段取值约束与主数据台账 | D37: 135 项
A40: ③ 编码规则（「02-基础参数表」编码列前缀）
A41: ORG- | B41: 组织主数据 | C41: 经营单位、项目公司、生产管理单元、计量点、绑定关系
A42: MD- | B42: 生产主数据 | C42: 产品型号、产品种类、产线、工序、映射关系、生产工单、统计期
A43: EN- | B43: 能源数据 | C43: 电 / 天然气 / 蒸汽 / 热力 / 油品 / 水等消耗量，综合能源消费量，折标系数引用
A44: OUT- | B44: 产量数据 | C44: 产品产量、工序产量、订单产量（变压器 / 线缆 / 铁心 / 电容器等）
A45: VAL- | B45: 产值数据 | C45: 工业增加值、产品产值、各工序对应产值
...

Sheet 02-基础参数表
A1: 序号 | B1: 编码 | C1: 名称 | D1: 类型 | E1: 符号 | F1: 参数类别 | G1: 数据说明 | H1: 单位 | I1: 数据格式 | J1: 小数位 | K1: 取值范围 / 枚举 | L1: 默认取值 / 参考值 | M1: 数据来源 | N1: 来源对象 / 字段 | O1: 获取方式 | P1: 更新频率 | Q1: 必填 | R1: 责任单位 | S1: 关联编码 | T1: 校验规则 | U1: 备注
A2: 1 | B2: CAR-001 | C2: 二氧化碳排放量 | D2: 参数 | E2: C | F2: 碳排放数据 | G2: 统计期内企业组织产生的二氧化碳总排放量（本次口径仅含能源碳排放） | H2: tCO2 | I2: 数值（3 位小数） | J2: 3 | K2: ≥0 | L2: — | M2: 集控中心（系统自动计算） | N2: 计算字段 | O2: 计算 | P2: 月度 | Q2: 是 | R2: 电装 | S2: IND-004、IND-005 | T2: ≥0 | U2: 生产过程排放与固碳数据难统计，本次不纳入
A3: 2 | B3: CAR-002 | C3: 化石燃料燃烧排放量 | D3: 参数 | E3: C燃烧 | F3: 碳排放数据 | G3: 化石燃料燃烧产生的二氧化碳排放量总和 | H3: tCO2 | I3: 数值（3 位小数） | J3: 3 | K3: ≥0 | L3: — | M3: 集控中心 | N3: 计算字段 | O3: 计算 | P3: 月度 | Q3: 是 | R3: 电装 | S3: IND-004 | T3: ≥0 | U3: 按燃料品种分别核算
A4: 3 | B4: CAR-003 | C4: 过程排放量 | D4: 参数 | E4: C过程 | F4: 碳排放数据 | G4: 工业生产过程产生的二氧化碳排放量总和 | H4: tCO2 | I4: 数值（3 位小数） | J4: 3 | K4: ≥0 | L4: 0 | M4: 集控中心 | N4: 计算字段 | O4: 计算 | P4: 月度 | Q4: 否 | R4: 电装 | S4: IND-004 | T4: ≥0 | U4: 当前口径按 0 处理
A5: 4 | B5: CAR-004 | C5: 购入电力排放量 | D5: 参数 | E5: C购入电 | F5: 碳排放数据 | G5: 购入电力对应的二氧化碳排放量 | H5: tCO2 | I5: 数值（3 位小数） | J5: 3 | K5: ≥0 | L5: — | M5: 集控中心 | N5: 计算字段 | O5: 计算 | P5: 月度 | Q5: 是 | R5: 电装 | S5: IND-004 | T5: ≥0 | U5: 采用省级电力平均排放因子 FAC-009
A6: 5 | B6: CAR-005 | C6: 输出电力排放量 | D6: 参数 | E6: C输出电 | F6: 碳排放数据 | G6: 输出电力对应的二氧化碳排放量（扣减项） | H6: tCO2 | I6: 数值（3 位小数） | J6: 3 | K6: ≥0 | L6: 0 | M6: 集控中心 | N6: 计算字段 | O6: 计算 | P6: 月度 | Q6: 否 | R6: 电装 | S6: IND-004 | T6: ≥0 | U6: 无电力输出时取 0
A7: 6 | B7: CAR-006 | C7: 购入热力排放量 | D7: 参数 | E7: C购入热 | F7: 碳排放数据 | G7: 购入热力对应的二氧化碳排放量 | H7: tCO2 | I7: 数值（3 位小数） | J7: 3 | K7: ≥0 | L7: — | M7: 集控中心 | N7: 计算字段 | O7: 计算 | P7: 月度 | Q7: 是 | R7: 电装 | S7: IND-004 | T7: ≥0 | U7: 热力排放因子见 FAC-013
A8: 7 | B8: CAR-007 | C8: 输出热力排放量 | D8: 参数 | E8: C输出热 | F8: 碳排放数据 | G8: 输出热力对应的二氧化碳排放量（扣减项） | H8: tCO2 | I8: 数值（3 位小数） | J8: 3 | K8: ≥0 | L8: 0 | M8: 集控中心 | N8: 计算字段 | O8: 计算 | P8: 月度 | Q8: 否 | R8: 电装 | S8: IND-004 | T8: ≥0 | U8: 无热力输出时取 0
A9: 8 | B9: CAR-008 | C9: 二氧化碳回收利用量 | D9: 参数 | E9: C回收利用 | F9: 碳排放数据 | G9: 化石燃料燃烧、工艺过程产生的 CO2 经回收自用或外供且确保未再次排放所对应的量（扣减项） | H9: tCO2 | I9: 数值（3 位小数） | J9: 3 | K9: ≥0 | L9: 0 | M9: 集控中心 | N9: 计算字段 | O9: 计算 | P9: 月度 | Q9: 否 | R9: 电装 | S9: IND-004 | T9: ≥0 | U9: 当前口径按 0 处理
A10: 9 | B10: CAR-009 | C10: 产品碳足迹值 | D10: 参数 | E10: CF | F10: 碳排放数据 | G10: 摇篮到大门阶段的产品碳足迹值，引用 GB/T 24067、ISO 14067 | H10: tCO2/台套、tCO2/km 等 | I10: 数值（4 位小数） | J10: 4 | K10: ≥0 | L10: — | M10: 碳足迹在线核算及报告系统 | N10: 碳足迹核算结果 | O10: 系统对接 | P10: 实时 / 月度 | Q10: 是 | R10: 各项目公司 | S10: IND-001 | T10: ≥0 | U10: 由碳足迹系统计算并回传集控 / 集采中心
A11: 10 | B11: CAR-010 | C11: 开展碳足迹分析的产品类别数量 | D11: 参数 | E11: Ncf | F11: 碳排放数据 | G11: 统计期内开展主要产品碳足迹分析的产品类别数量 | H11: 个 | I11: 数值（0 位小数） | J11: 0 | K11: ≥0 | L11: — | M11: 碳足迹在线核算及报告系统 | N11: 核算报告台账 | O11: 系统对接 | P11: 月度 | Q11: 是 | R11: 各项目公司 | S11: IND-002 | T11: ≥0 且 ≤ 主要产品类别总数 | U11: 系统提供开展计算的产品种类明细
A12: 11 | B12: CAR-011 | C12: 主要产品类别总数 | D12: 参数 | E12: N | F12: 碳排放数据 | G12: 单位全部主要产品类别数量 | H12: 个 | I12: 数值（0 位小数） | J12: 0 | K12: >0 | L12: — | M12: ERP 系统 | N12: 物料主数据.产品类别 | O12: 系统对接 | P12: 月度 | Q12: 是 | R12: 各项目公司 | S12: IND-002 | T12: >0 | U12: 从 ERP 获取全部产品种类明细
A13: 12 | B13: CAR-012 | C13: 净购入电力消费量 | D13: 参数 | E13: — | F13: 碳排放数据 | G13: 购入电力扣除输出电力后的净消费量，用于碳排放核算 | H13: MWh | I13: 数值（2 位小数） | J13: 2 | K13: ≥0 | L13: — | M13: 集控中心 | N13: 计算字段 | O13: 计算 | P13: 月度 | Q13: 是 | R13: 电装 | S13: IND-004 | T13: ≥0 | U13: —
... A192: 191 | B192: VAL-012 | C192: 工序产值 | D192: 参数 | E192: G* | F192: 产值数据 | G192: 关键工序单位产值类指标的通用分母 | H192: 万元 | I192: 数值（2 位小数） | J192: 2 | K192: >0 | L192: — | M192: 见各项目公司来源 | N192: 产值记录 | O192: 系统对接 / 手工录入 | P192: 月度 | Q192: 是 | R192: 各项目公司 | S192: IND-066~IND-090 | T192: >0；分母为空或 0 时指标置空 | U192: 计算时须做分母空值 / 0 保护

Sheet 03-指标清单
A1: 序号 | B1: 指标编码 | C1: 指标名称 | D1: 指标层级 | E1: 指标定义 | F1: 计算公式 | G1: 指标说明（公式变量定义） | H1: 指标单位 | I1: 所属中心 | J1: 指标类别 | K1: 指标来源 | L1: 指标用途 | M1: 覆盖范围 | N1: 所需各单位数据 | O1: 涉及参数编码 | P1: 各单位所需开展工作 | Q1: 备注
A2: 1 | B2: IND-001 | C2: 产品碳足迹 | D2: 经营单位及项目公司整体指标（重点对标国家零碳工厂要求） | E2: 引用GB/T 24067、ISO14067，主要管理摇篮到大门阶段的产品碳足迹。 | F2: CF = Σ(活动数据i × 排放因子i)（摇篮到大门阶段） | G2: 实时数据，产品碳足迹值 | H2: tCo2/台套，tCo2/km等 | I2: 集采 | J2: 产品 | K2: 外部要求（应对CBAM及绿色招采) | L2: 自动计算，减少收资，快速应对客户招采对碳足迹的要求 | M2: 沈变：沈变本部、和新套管、康嘉互感器 / 衡变：本部、南京电研、云集电气、湖南电气、云集高压开关、新疆自控、特能建、合容电气、赛杰爱迪 / 新变：超高压公司、天变公司、智能电气、京津冀智能科技、珠峰硅钢 / 鲁缆：鲁缆本部、曙光公司 / 德缆：德缆 / 新缆：新疆电缆公司、新疆线缆厂 | N2: 生产工单、物料、能耗数据。 | O2: — | P2: 各项目公司部署电装下发的碳足迹数据采集模块，开展实施工作，包括：（1）进行相关配置；（2）打通BOM、工单、能源类数据，进行联调。所需开展实施工作明细后续下发指导手册。
A3: 2 | B3: IND-002 | C3: 开展产品碳足迹分析占比 | D3: 经营单位及项目公司整体指标（重点对标国家零碳工厂要求） | E3: 指统计期内开展主要产品碳足迹分析的产品类别数量占主要产品类别总数的比值 | F3: Rcf = Ncf / N | G3: 月度指标。 Rcf：开展产品碳足迹分析占比； Ncf:开展主要产品碳足迹分析的产品类别数量; N:主要产品类别总数 | H3: % | I3: 集采 | J3: 工厂 | K3: 国家级零碳工厂 | L3: 支撑绿色低碳管理体系、绿色低碳发展规划、温室气体盘查、能源管理体系、清洁生产、零碳工厂、绿色工厂等工作的开展 | N3: 产品碳足迹系统提供开展产品碳足迹计算的产品种类明细。从ERP系统获取各单位全部产品种类明细。 | O3: CAR-010、CAR-011 | P3: 完成碳足迹数据采集模块的部署、配置，在电装统一部署的碳足迹在线核算及报告系统中完成能源-生产绑定工作。
A4: 3 | B4: IND-003 | C4: 综合能源消费量 | D4: 经营单位及项目公司整体指标（重点对标国家零碳工厂要求） | E4: 指统计期内组织综合能源消费的总吨标准煤 | F4: E = Σ(Ei × ki) (i = 1..n) | G4: 月度指标 E：综合能源消耗量，单位为tce n：消耗的能源种类数 Ei:实际消耗的第i种能源量 ki:第i种能源的折标准煤系数 | H4: tce | I4: 集控 | J4: 工厂 | K4: 国家级零碳工厂 | N4: 电（包括市电和绿电）、天然气、蒸汽、热力、柴油、煤油汽油等所有消耗能源种类的消耗量。其中核算综合能源消费量时，电力折标煤系数用当量值。 | O4: EN-014、EN-015、EN-016 | P4: 1、各经营单位及项目公司完成电力、蒸汽、热力能源数据采集，并通过系统自动上送电装； / 2、各经营单位及项目公司在集控中心开放的录入界面中按月录入购买绿电、绿证量，及按月录入难以自动采集的天然气、柴油、煤油、汽油（若能自动采集，则优先取自动采集数据，并通过系统自动上送电装）。 / 3、相关折标煤系数、碳排放因子由电装统一维护，各类指标电装统一计算。
A5: 4 | B5: IND-004 | C5: 总碳排放量 | D5: 经营单位及项目公司整体指标（重点对标国家零碳工厂要求） | E5: 指统计期内企业组织产生的二氧化碳总排放量 | F5: C = C燃烧 + C过程 + C购入电 + C购入热 − C输出电 − C输出热 − C回收利用 | G5: 月度指标。由于电装产业在生产过程碳排放、回收利用中固碳非常少，且数据难统计，本次考虑能源碳排放。 C：二氧化碳排放量，单位为吨二氧化碳（tCO2）； C燃烧：化石燃料燃烧产生的二氧化碳排放量总和，单位为吨二氧化碳（tCO2） C过程：过程二氧化碳排放量总和，单位为吨二氧化碳（tCO2） C购入电：购入的电力所产生的二氧化碳排放，单位为吨二氧化碳（tCO2） C输出电：输出的电力所产生的二氧化碳排放，单位为吨二氧化碳（tCO2） C购入热：购入的热力所产生的二氧化碳排放，单位为吨二氧化碳（tCO2） C输出热：输出的热力所产生的二氧化碳排放，单位为吨二氧化碳（tCO2） C回收利用：化石燃料燃烧、工艺过程产生的二氧化碳经回收作为生产原料自用或作为产品外供并确保未再次排放所对应的二氧化碳排放量，单位为吨二氧化碳（tCO2） | H5: tCO2 | I5: 集控 | J5: 工厂 | K5: 国家级零碳工厂 | N5: 电（包括市电和绿电）、天然气、蒸汽、热力、柴油、煤油汽油等所有消耗能源种类的月度消耗量。电力消费量计算碳排放取省级电力平均二氧化碳排放因子。 | O5: CAR-002、CAR-003、CAR-004、CAR-005、CAR-006、CAR-007、CAR-008
A6: 5 | B6: IND-005 | C6: 单位能耗碳排放 | D6: 经营单位及项目公司整体指标（重点对标国家零碳工厂要求） | E6: 指统计期内每消费一吨标准煤产生的二氧化碳排放量 | F6: I = C / E | G6: 月度指标。 I:单位能耗碳排放 C：二氧化碳排放量，单位为tCO2 E：综合能源消耗量，单位为tce | H6: tCO2/tce | I6: 集控 | J6: 工厂 | K6: 国家级零碳工厂 | N6: 分子与分母的核算范围须保持一致。提供电（包括市电和绿电）、天然气、蒸汽、热力、柴油、煤油汽油等所有消耗能源种类的消耗量。其中电力消费量折算标煤按照等价值计算（电力标煤系数优先使用所在省的平均发电煤耗，无法获取的，使用0.2856kgce/kWh） | O6: CAR-001、EN-013
A7: 6 | B7: IND-006 | C7: 非化石能源消费占比 | D7: 经营单位及项目公司整体指标（重点对标国家零碳工厂要求） | E7: 指统计期内非化石能源消费量与综合能源消费量的比值 | F7: r = R / E | G7: 月度指标，交易绿电、绿证可纳入分子。 r：非化石能源消费占比 R:各类非化石能源消费量(不含作为原料使用的能源)，单位为tce E:综合能源消费量（不含作为原料使用的能源）,单位为tce | H7: % | I7: 集控 | J7: 工厂 | K7: 国家级零碳工厂 | N7: ①绿电等非化石能源的月度消耗量； / ②电（包括市电和绿电）、天然气、蒸汽、热力、柴油、煤油汽油等所有消耗能源种类的消耗量。 | O7: EN-017、EN-013
A8: 7 | B8: IND-007 | C8: 非化石能源电力消费物理认定量占比 | D8: 经营单位及项目公司整体指标（重点对标国家零碳工厂要求） | E8: 指统计期内具备物理可溯源条件的非化石能源电力消费量占同期总用电量的比值。 | F8: Eui = Ez / Q | G8: 月底指标，交易绿电、绿证不纳入分子。 Eui:非化石能源电力消费物理认定量占比； Ez:具备物理可溯源条件的非化石能源电力消费量，单位为kWh; Q:总用电量，单位为千kWh | H8: % | I8: 集控 | J8: 工厂 | K8: 国家级零碳工厂 | N8: 月度总用电量和具备物理可溯源条件的非化石能源电力消耗量（如自建消纳绿电及非自建绿电直连量） | O8: EN-005、EN-020
A9: 8 | B9: IND-008 | C9: 单位工业增加值能耗 | D9: 经营单位及项目公司整体指标（重点对标国家零碳工厂要求） | E9: 指统计期内综合能源消费量与工业增加值的比值 | F9: Enva = E / Gnva | G9: 月度指标，年度重新汇算。 Enva:单位工业增加值能耗，单位为tce/万元； E：综合能源消费量，单位tce Gnva:工业增加值，单位为万元 | H9: tce/万元 | I9: 集控 | J9: 工厂 | K9: 国家级零碳工厂 | N9: ①企业月度工业增加值； / ②电（包括市电和绿电）、天然气、蒸汽、热力、柴油、煤油汽油等所有消耗能源种类的消耗量。 | O9: EN-013、VAL-001 | P9: 各经营单位及项目公司在集控中心开放的界面中录入企业工业增加值，月度估算，年度汇算。
A10: 9 | B10: IND-009 | C10: 节能装备应用占比 | D10: 经营单位及项目公司整体指标（重点对标国家零碳工厂要求） | E10: 指统计期内达到或优于能效强制性国家标准 2 级水平和《重点用能产品设备能效先进水平、节能水平和准入水平》节能水平的装备累计额定总功率占纳入统计范围装备累计额定总功率的比例 | F10: S = Res / Ets | G10: 月度指标。 S：节能装备应用占比； Res:达到或优于能效强制性国家标准 2 级水平和《重点用能产品设备能效先进水平、节能水平和准入水平》节能水平的装备累计额定总功率，单位为kW。 Ets:纳入统计范围装备累计额定总功率，单位为kW。纳入统计范围的装备需有适用的能效强制性国家标准，包括但不限于电动机、变压器、工业锅炉、风机、容积式空气压缩机、工业制冷设备、热泵等；无适用标准的装备不纳入统计。 | H10: % | I10: 集控 | J10: 工厂 | K10: 国家级零碳工厂 | N10: ①达到要求节能水平的装备累计额定总功率。 / ②企业所有装备累计额定总功率。 | O10: EQ-001、EQ-002 | P10: 各经营单位及项目公司在集控中心开放的界面中录入节能装备明细、所有装备明细，增量更新。
A11: 10 | B11: IND-010 | C11: 单位产值能耗 | D11: 经营单位及项目公司整体指标（重点对标国家零碳工厂要求） | E11: 指统计期内综合能源消费量与产品产值的比值 | F11: g = E / G | G11: 月度指标。 g:单位产值能耗，单位为tce/万元； E：综合能源消费量，单位tce G:产品产值，单位为万元 | H11: tce/万元 | I11: 集控 | J11: 工厂 | K11: 股份管理要求 | N11: ①各单位产值，其中线缆产值到产线，从大数据平台获取，日更新。变压器产值到项目公司，从经营日报管理系统获取，日更新。 / ②电（包括市电和绿电）、天然气、蒸汽、热力、柴油、煤油汽油等所有消耗能源种类的消耗量。 | O11: EN-013、VAL-002 | P11: 线缆产值在电装大数据平台，变压器产值在经营日报管理系统，以各经营单位及项目公司为对象进行计算。
A12: 11 | B12: IND-011 | C12: 水资源消耗量 | D12: 经营单位及项目公司整体指标（重点对标国家零碳工厂要求） | E12: 指企业在一定时期内，实际用于生产、生活等用途中未返回环境或未再次回用的水量 | F12: W = Σ各计量点用水量（生产用水 + 生活用水） | G12: 月度指标。 | H12: t | I12: 集控 | J12: 工厂 | K12: ESG要求 | N12: ①各单位按照月度上报实际生活生产用水量； / ②有中水或其他再生水使用的单位应该考虑循环使用量经计算处理后上报集团。 | O12: — | P12: 无法通过系统上送数据的单位可以手动定期录入数据
A13: 12 | B13: IND-012 | C13: 单位产品能耗（型号、ERP产品种类、电装产线大类） | D13: 产品管控指标（最小到型号级别） | E13: 指统计期内综合能源总消费量与产品产量的比值 | F13: e = E / M | G13: 月度指标。 e:单位产品能耗，单位为tce/产品单位； E：综合能源消费量，单位tce M:产品产量，单位为产品单位，如万kVA、万km*mm2等 | H13: tce/产品单位（例如万kVA、万km*mm2） | I13: 集控 | J13: 工厂 | K13: 电装管理要求 | L13: 电装内部管理，实现同类型产品横向（不同单位间）、纵向（不同时间段间）对比分析，实现与行业基准、行业标杆的对比 | M13: 沈变：沈变本部 / 衡变：本部、湖南电气、特能建 / 新变：超高压公司、天变公司、智能电气、京津冀智能科技 / 鲁缆：鲁缆本部、曙光公司 / 德缆：德缆 / 新缆：新疆电缆公司、新疆线缆厂 | N13: ①订单产量、订单型号； / ②订单所消耗能源量：电（包括市电和绿电）、天然气、蒸汽、热力等。 / ③型号-产品种类-产线的对应关系。 | O13: EN-013、OUT-008 | P13: 1、各项目公司完成关键工序、车间用能的采集，并对接至本地数据采集模块； / 2、各项目公司在碳足迹在线核算及报告系统，生产-能源绑定模块完成生产管理单元与能耗计量的绑定； / 3、各项目公司按标准接口将生产工单传送至本地数据采集模块。
A14: 13 | B14: IND-013 | C14: 单位产品电耗 | D14: 产品管控指标（最小到型号级别） | E14: 指统计期内电能源消费量（包括公辅设备）与产品产量的比值 | F14: q电 = Q电 / M | G14: 月度指标。 q电:单位产品电耗，单位为kWh/产品单位； Q电：电能源消费量，单位kWh M:产品产量，单位为产品单位，如万kVA、万km*mm2等 | H14: kWh/产品单位（例如万kVA、万km*mm2） | I14: 集控 | J14: 公司级 | K14: 电装管理要求 | N14: ①订单产量、订单型号； / ②订单所消耗电（包括市电和绿电）。 / ③型号-产品种类-产线的对应关系。 | O14: EN-001、OUT-008
A15: 14 | B15: IND-014 | C15: 单位产品蒸汽消耗 | D15: 产品管控指标（最小到型号级别） | E15: 指统计期内蒸汽能源消费量与产品产量的比值 | F15: q蒸汽 = Q蒸汽 / M | G15: 月度指标。 q蒸汽:单位产品蒸汽消耗，单位为GJ/产品单位； Q蒸汽：蒸汽能源消费量，单位GJ M:产品产量，单位为产品单位，如万kVA、万km*mm2等 | H15: GJ/产品单位（例如万kVA、万km*mm2） | I15: 集控 | J15: 公司级 | K15: 电装管理要求 | N15: ①订单产量、订单型号； / ②订单所消耗蒸汽。 / ③型号-产品种类-产线的对应关系。 | O15: EN-007、OUT-008
A16: 15 | B16: IND-015 | C16: 单位产品天然气消耗 | D16: 产品管控指标（最小到型号级别） | E16: 指统计期内天然气能源消费量与产品产量的比值 | F16: q天然气 = Q天然气 / M | G16: 月度指标。 q天然气:单位产品天然气消耗，单位为m³/产品单位； Q天然气：天然气能源消费量，单位m³ M:产品产量，单位为产品单位，如万kVA、万km*mm2等 | H16: m³/产品单位（例如万kVA、万km*mm2） | I16: 集控 | J16: 公司级 | K16: 电装管理要求 | N16: ①订单产量、订单型号； / ②订单所消耗天然气。 / ③型号-产品种类-产线的对应关系。 | O16: EN-006、OUT-008
A17: 16 | B17: IND-016 | C17: 单位产品水耗 | D17: 产品管控指标（最小到型号级别） | E17: 指统计期内水能源消费量与产品产量的比值 | F17: q水 = Q水 / M | G17: 月度指标。 q水:单位产品水耗，单位为t/产品单位； Q水：水能源消费量，单位t M:产品产量，单位为产品单位，如万kVA、万km*mm2等 | H17: t/产品单位（例如万kVA、万km*mm2） | I17: 集控 | J17: 公司级 | K17: 电装管理要求 | N17: ①订单产量、订单型号； / ②订单所消耗水。 / ③型号-产品种类-产线的对应关系。 | O17: EN-026、OUT-008
A18: 17 | B18: IND-017 | C18: 吨铜电耗（线缆-导线-拉丝） | D18: 关键工序管控指标（分产业设置，管控能耗较高的工序） | E18: 线缆导线产线，拉丝工序，拉1吨铜耗电量 | F18: q线缆-导线-拉丝Cu-电 = Q线缆-导线-拉丝Cu-电 / M线缆-导线-拉丝Cu | G18: 月度指标 q线缆-导线-拉丝Cu-电：导线产线中拉丝工序单位铜电耗，单位为kWh/t； Q线缆-导线-拉丝Cu-电：导线产线中拉丝工序电能源消费量，单位kWh M线缆-导线-拉丝Cu:导线产线中拉丝工序铜产量，单位为t | H18: kWh/t | I18: 集控 | J18: 关键工序 | K18: 电装管理要求 | L18: 电装内部管理，管控高能耗工序，用指标牵引项目公司主动节能，通过数据分析挖掘节能空间 | M18: 鲁缆本部、新疆线缆厂、德缆公司 | N18: ①导线产线拉丝工序耗电量 / ②对应耗铜量 | O18: EN-021、OUT-008 | P18: 采集拉丝（铜）设备的电耗，统计耗铜量，上送电装集控中心。
A19: 18 | B19: IND-018 | C19: 吨铝电耗（线缆-导线-拉丝） | D19: 关键工序管控指标（分产业设置，管控能耗较高的工序） | E19: 线缆导线产线，拉丝工序，拉1吨铝耗电量 | F19: q线缆-导线-拉丝Al-电 = Q线缆-导线-拉丝Al-电 / M线缆-导线-拉丝Al | G19: 月度指标 q线缆-导线-拉丝Al-电：导线产线中拉丝工序单位铝电耗，单位为kWh/t； Q线缆-导线-拉丝Al-电：导线产线中拉丝工序电能源消费量，单位kWh M线缆-导线-拉丝Al:导线产线中拉丝工序铝产量，单位为t | H19: kWh/t | I19: 集控 | J19: 关键工序 | K19: 电装管理要求 | N19: ①导线产线拉丝工序耗电量 / ②对应耗铝量 | O19: EN-021、OUT-008 | P19: 采集拉丝（铝）设备的电耗，统计耗铝量，上送电装集控中心。
A20: 19 | B20: IND-019 | C20: 吨铜电耗（线缆-布电线-拉丝） | D20: 关键工序管控指标（分产业设置，管控能耗较高的工序） | E20: 线缆布电线产线，拉丝工序，拉1吨铜耗电量 | F20: q线缆-布电线-拉丝Cu-电 = Q线缆-布电线-拉丝Cu-电 / M线缆-布电线-拉丝Cu | G20: 月度指标 q线缆-布电线-拉丝Cu-电：布电线产线中拉丝工序单位铜电耗，单位为kWh/t； Q线缆-布电线-拉丝Cu-电：布电线产线中拉丝工序电能源消费量，单位kWh M线缆-布电线-拉丝Cu:布电线产线中拉丝工序铜产量，单位为t | H20: kWh/t | I20: 集控 | J20: 关键工序 | K20: 电装管理要求 | M20: 鲁缆本部、新疆线缆厂、新疆电缆、德缆公司 | N20: ①布电线产线拉丝工序耗电量 / ②对应耗铜量 | O20: EN-021、OUT-008 | P20: 采集拉丝（铜）设备的电耗，统计耗铜量，上送电装集控中心。
A21: 20 | B21: IND-020 | C21: 吨铝电耗（线缆-布电线-拉丝） | D21: 关键工序管控指标（分产业设置，管控能耗较高的工序） | E21: 线缆布电线产线，拉丝工序，拉1吨铝耗电量 | F21: q线缆-布电线-拉丝Al-电 = Q线缆-布电线-拉丝Al-电 / M线缆-布电线-拉丝Al | G21: 月度指标 q线缆-布电线-拉丝Al-电：布电线产线中拉丝工序单位铝电耗，单位为kWh/t； Q线缆-布电线-拉丝Al-电：布电线产线中拉丝工序电能源消费量，单位kWh M线缆-布电线-拉丝Al:布电线产线中拉丝工序铝产量，单位为t | H21: kWh/t | I21: 集控 | J21: 关键工序 | K21: 电装管理要求 | N21: ①布电线产线拉丝工序耗电量 / ②对应耗铝量 | O21: EN-021、OUT-008 | P21: 采集拉丝（铝）设备的电耗，统计耗铝量，上送电装集控中心。
A22: 21 | B22: IND-021 | C22: 吨铜电耗（线缆-高压电缆-拉丝） | D22: 关键工序管控指标（分产业设置，管控能耗较高的工序） | E22: 线缆高压电缆产线，拉丝工序，拉1吨铜耗电量 | F22: q线缆-高压电缆-拉丝Cu-电 = Q线缆-高压电缆-拉丝Cu-电 / M线缆-高压电缆-拉丝Cu | G22: 月度指标 q线缆-高压电缆-拉丝Cu-电：高压电缆产线中拉丝工序单位铜电耗，单位为kWh/t； Q线缆-高压电缆-拉丝Cu-电：高压电缆产线中拉丝工序电能源消费量，单位kWh M线缆-高压电缆-拉丝Cu:高压电缆产线中拉丝工序铜产量，单位为t | H22: kWh/t | I22: 集控 | J22: 关键工序 | K22: 电装管理要求 | M22: 鲁缆本部 | N22: ①高压电缆产线拉丝工序耗电量 / ②对应耗铜量 | O22: EN-021、OUT-008 | P22: 采集拉丝（铜）设备的电耗，统计耗铜量，上送电装集控中心。
A23: 22 | B23: IND-022 | C23: 吨铝电耗（线缆-高压电缆-拉丝） | D23: 关键工序管控指标（分产业设置，管控能耗较高的工序） | E23: 线缆高压电缆产线，拉丝工序，拉1吨铝耗电量 | F23: q线缆-高压电缆-拉丝Al-电 = Q线缆-高压电缆-拉丝Al-电 / M线缆-高压电缆-拉丝Al | G23: 月度指标 q线缆-高压电缆-拉丝Al-电：高压电缆产线中拉丝工序单位铝电耗，单位为kWh/t； Q线缆-高压电缆-拉丝Al-电：高压电缆产线中拉丝工序电能源消费量，单位kWh M线缆-高压电缆-拉丝Al:高压电缆产线中拉丝工序铝产量，单位为t | H23: kWh/t | I23: 集控 | J23: 关键工序 | K23: 电装管理要求 | N23: ①高压电缆产线拉丝工序耗电量 / ②对应耗铝量 | O23: EN-021、OUT-008 | P23: 采集拉丝（铝）设备的电耗，统计耗铝量，上送电装集控中心。
A24: 23 | B24: IND-023 | C24: 高压交联（干法）（线缆-高压电缆-交联） | D24: 关键工序管控指标（分产业设置，管控能耗较高的工序） | E24: 线缆高压电缆产线，交联工序，单位产量耗电量。 | F24: q线缆-高压电缆-交联-电 = Q线缆-高压电缆-交联-电 / M线缆-高压电缆-交联 | G24: 月度指标 q线缆-高压电缆-交联-电：高压电缆产线中交联工序单位产品电耗，单位为kWh/km*mm2； Q线缆-高压电缆-交联-电：高压电缆产线中交联工序电能源消费量，单位kWh M线缆-高压电缆-交联:高压电缆产线中交联工序产品产量，单位为km*mm2 | H24: kWh/km*mm2 | I24: 集控 | J24: 关键工序 | K24: 电装管理要求 | N24: ①高压电缆产线交联工序耗电量 / ②对应线缆产量。ERP里有，入库的公里数*截面，km*mm2 | O24: EN-021、OUT-008 | P24: 采集高压产线交联设备的电耗，统计对应线缆产量，上送电装集控中心。
A25: 24 | B25: IND-024 | C25: 吨铜电耗（线缆-中压电缆-拉丝） | D25: 关键工序管控指标（分产业设置，管控能耗较高的工序） | E25: 线缆中压电缆产线，拉丝工序，拉1吨铜耗电量 | F25: q线缆-中压电缆-拉丝Cu-电 = Q线缆-中压电缆-拉丝Cu-电 / M线缆-中压电缆-拉丝Cu | G25: 月度指标 q线缆-中压电缆-拉丝Cu-电：中压电缆产线中拉丝工序单位铜电耗，单位为kWh/t； Q线缆-中压电缆-拉丝Cu-电：中压电缆产线中拉丝工序电能源消费量，单位kWh M线缆-中压电缆-拉丝Cu:中压电缆产线中拉丝工序铜产量，单位为t | H25: kWh/t | I25: 集控 | J25: 关键工序 | K25: 电装管理要求 | M25: 鲁缆本部、新疆线缆厂、新疆电缆、德缆公司 | N25: ①中压电缆产线拉丝工序耗电量 / ②对应耗铜量 | O25: EN-021、OUT-008 | P25: 采集拉丝（铜）设备的电耗，统计耗铜量，上送电装集控中心。
A26: 25 | B26: IND-025 | C26: 吨铝电耗（线缆-中压电缆-拉丝） | D26: 关键工序管控指标（分产业设置，管控能耗较高的工序） | E26: 线缆中压电缆产线，拉丝工序，拉1吨铝耗电量 | F26: q线缆-中压电缆-拉丝Al-电 = Q线缆-中压电缆-拉丝Al-电 / M线缆-中压电缆-拉丝Al | G26: 月度指标 q线缆-中压电缆-拉丝Al-电：中压电缆产线中拉丝工序单位铝电耗，单位为kWh/t； Q线缆-中压电缆-拉丝Al-电：中压电缆产线中拉丝工序电能源消费量，单位kWh M线缆-中压电缆-拉丝Al:中压电缆产线中拉丝工序铝产量，单位为t | H26: kWh/t | I26: 集控 | J26: 关键工序 | K26: 电装管理要求 | N26: ①中压电缆产线拉丝工序耗电量 / ②对应耗铝量 | O26: EN-021、OUT-008 | P26: 采集拉丝（铝）设备的电耗，统计耗铝量，上送电装集控中心。
A27: 26 | B27: IND-026 | C27: 中压交联（干法）（线缆-中压电缆-交联） | D27: 关键工序管控指标（分产业设置，管控能耗较高的工序） | E27: 线缆中压电缆产线，交联工序，单位产量耗电量。 | F27: q线缆-中压电缆-交联-电 = Q线缆-中压电缆-交联-电 / M线缆-中压电缆-交联 | G27: 月度指标 q线缆-中压电缆-交联-电：中压电缆产线中交联工序单位产品电耗，单位为kWh/km*mm2； Q线缆-中压电缆-交联-电：中压电缆产线中交联工序电能源消费量，单位kWh M线缆-中压电缆-交联:中压电缆产线中交联工序产品产量，单位为km*mm2 | H27: kWh/km*mm2 | I27: 集控 | J27: 关键工序 | K27: 电装管理要求 | N27: ①中压电缆产线交联工序耗电量 / ②对应线缆产量。ERP里有，入库的公里数*截面，km*mm2 | O27: EN-021、OUT-008 | P27: 采集中压产线交联设备的电耗，统计对应线缆产量，上送电装集控中心。
A28: 27 | B28: IND-027 | C28: 吨铜电耗（线缆-低压电缆-拉丝） | D28: 关键工序管控指标（分产业设置，管控能耗较高的工序） | E28: 线缆低压电缆产线，拉丝工序，拉1吨铜耗电量 | F28: q线缆-低压电缆-拉丝Cu-电 = Q线缆-低压电缆-拉丝Cu-电 / M线缆-低压电缆-拉丝Cu | G28: 月度指标 q线缆-低压电缆-拉丝Cu-电：低压电缆产线中拉丝工序单位铜电耗，单位为kWh/t； Q线缆-低压电缆-拉丝Cu-电：低压电缆产线中拉丝工序电能源消费量，单位kWh M线缆-低压电缆-拉丝Cu:低压电缆产线中拉丝工序铜产量，单位为t | H28: kWh/t | I28: 集控 | J28: 关键工序 | K28: 电装管理要求 | N28: ①低压电缆产线拉丝工序耗电量 / ②对应耗铜量 | O28: EN-021、OUT-008 | P28: 采集拉丝（铜）设备的电耗，统计耗铜量，上送电装集控中心。
A29: 28 | B29: IND-028 | C29: 吨铝电耗（线缆-低压电缆-拉丝） | D29: 关键工序管控指标（分产业设置，管控能耗较高的工序） | E29: 线缆低压电缆产线，拉丝工序，拉1吨铝耗电量 | F29: q线缆-低压电缆-拉丝Al-电 = Q线缆-低压电缆-拉丝Al-电 / M线缆-低压电缆-拉丝Al | G29: 月度指标 q线缆-低压电缆-拉丝Al-电：低压电缆产线中拉丝工序单位铝电耗，单位为kWh/t； Q线缆-低压电缆-拉丝Al-电：低压电缆产线中拉丝工序电能源消费量，单位kWh M线缆-低压电缆-拉丝Al:低压电缆产线中拉丝工序铝产量，单位为t | H29: kWh/t | I29: 集控 | J29: 关键工序 | K29: 电装管理要求 | N29: ①低压电缆产线拉丝工序耗电量 / ②对应耗铝量 | O29: EN-021、OUT-008 | P29: 采集拉丝（铝）设备的电耗，统计耗铝量，上送电装集控中心。
A30: 29 | B30: IND-029 | C30: 吨铜电耗（线缆-特种电缆-拉丝） | D30: 关键工序管控指标（分产业设置，管控能耗较高的工序） | E30: 线缆特种电缆产线，拉丝工序，拉1吨铜耗电量 | F30: q线缆-特种电缆-拉丝Cu-电 = Q线缆-特种电缆-拉丝Cu-电 / M线缆-特种电缆-拉丝Cu | G30: 月度指标 q线缆-特种电缆-拉丝Cu-电：特种电缆产线中拉丝工序单位铜电耗，单位为kWh/t； Q线缆-特种电缆-拉丝Cu-电：特种电缆产线中拉丝工序电能源消费量，单位kWh M线缆-特种电缆-拉丝Cu:特种电缆产线中拉丝工序铜产量，单位为t | H30: kWh/t | I30: 集控 | J30: 关键工序 | K30: 电装管理要求 | N30: ①特种电缆产线拉丝工序耗电量 / ②对应耗铜量 | O30: EN-021、OUT-008 | P30: 采集拉丝（铜）设备的电耗，统计耗铜量，上送电装集控中心。
A31: 30 | B31: IND-030 | C31: 吨铝电耗（线缆-特种电缆-拉丝） | D31: 关键工序管控指标（分产业设置，管控能耗较高的工序） | E31: 线缆特种电缆产线，拉丝工序，拉1吨铝耗电量 | F31: q线缆-特种电缆-拉丝Al-电 = Q线缆-特种电缆-拉丝Al-电 / M线缆-特种电缆-拉丝Al | G31: 月度指标 q线缆-特种电缆-拉丝Al-电：特种电缆产线中拉丝工序单位铝电耗，单位为kWh/t； Q线缆-特种电缆-拉丝Al-电：特种电缆产线中拉丝工序电能源消费量，单位kWh M线缆-特种电缆-拉丝Al:特种电缆产线中拉丝工序铝产量，单位为t | H31: kWh/t | I31: 集控 | J31: 关键工序 | K31: 电装管理要求 | N31: ①特种电缆产线拉丝工序耗电量 / ②对应耗铝量 | O31: EN-021、OUT-008 | P31: 采集拉丝（铝）设备的电耗，统计耗铝量，上送电装集控中心。
A32: 31 | B32: IND-031 | C32: 吨铜电耗（线缆-装备电缆-拉丝） | D32: 关键工序管控指标（分产业设置，管控能耗较高的工序） | E32: 线缆装备电缆产线，拉丝工序，拉1吨铜耗电量 | F32: q线缆-装备电缆-拉丝Cu-电 = Q线缆-装备电缆-拉丝Cu-电 / M线缆-装备电缆-拉丝Cu | G32: 月度指标 q线缆-装备电缆-拉丝Cu-电：装备电缆产线中拉丝工序单位铜电耗，单位为kWh/t； Q线缆-装备电缆-拉丝Cu-电：装备电缆产线中拉丝工序电能源消费量，单位kWh M线缆-装备电缆-拉丝Cu:装备电缆产线中拉丝工序铜产量，单位为t | H32: kWh/t | I32: 集控 | J32: 关键工序 | K32: 电装管理要求 | N32: ①装备电缆产线拉丝工序耗电量 / ②对应耗铜量 | O32: EN-021、OUT-008 | P32: 采集拉丝（铜）设备的电耗，统计耗铜量，上送电装集控中心。
A33: 32 | B33: IND-032 | C33: 吨铝电耗（线缆-装备电缆-拉丝） | D33: 关键工序管控指标（分产业设置，管控能耗较高的工序） | E33: 线缆装备电缆产线，拉丝工序，拉1吨铝耗电量 | F33: q线缆-装备电缆-拉丝Al-电 = Q线缆-装备电缆-拉丝Al-电 / M线缆-装备电缆-拉丝Al | G33: 月度指标 q线缆-装备电缆-拉丝Al-电：装备电缆产线中拉丝工序单位铝电耗，单位为kWh/t； Q线缆-装备电缆-拉丝Al-电：装备电缆产线中拉丝工序电能源消费量，单位kWh M线缆-装备电缆-拉丝Al:装备电缆产线中拉丝工序铝产量，单位为t | H33: kWh/t | I33: 集控 | J33: 关键工序 | K33: 电装管理要求 | N33: ①装备电缆产线拉丝工序耗电量 / ②对应耗铝量 | O33: EN-021、OUT-008 | P33: 采集拉丝（铝）设备的电耗，统计耗铝量，上送电装集控中心。
A34: 33 | B34: IND-033 | C34: 吨铜电耗（线缆-橡套电缆-拉丝） | D34: 关键工序管控指标（分产业设置，管控能耗较高的工序） | E34: 线缆橡套电缆产线，拉丝工序，拉1吨铜耗电量 | F34: q线缆-橡套电缆-拉丝Cu-电 = Q线缆-橡套电缆-拉丝Cu-电 / M线缆-橡套电缆-拉丝Cu | G34: 月度指标 q线缆-橡套电缆-拉丝Cu-电：橡套电缆产线中拉丝工序单位铜电耗，单位为kWh/t； Q线缆-橡套电缆-拉丝Cu-电：橡套电缆产线中拉丝工序电能源消费量，单位kWh M线缆-橡套电缆-拉丝Cu:橡套电缆产线中拉丝工序铜产量，单位为t | H34: kWh/t | I34: 集控 | J34: 关键工序 | K34: 电装管理要求 | M34: 鲁缆本部、新疆线缆厂、德缆公司 | N34: ①橡套电缆产线拉丝工序耗电量 / ②对应耗铜量 | O34: EN-021、OUT-008 | P34: 采集拉丝（铜）设备的电耗，统计耗铜量，上送电装集控中心。
A35: 34 | B35: IND-034 | C35: 吨铝电耗（线缆-橡套电缆-拉丝） | D35: 关键工序管控指标（分产业设置，管控能耗较高的工序） | E35: 线缆橡套电缆产线，拉丝工序，拉1吨铝耗电量 | F35: q线缆-橡套电缆-拉丝Al-电 = Q线缆-橡套电缆-拉丝Al-电 / M线缆-橡套电缆-拉丝Al | G35: 月度指标 q线缆-橡套电缆-拉丝Al-电：橡套电缆产线中拉丝工序单位铝电耗，单位为kWh/t； Q线缆-橡套电缆-拉丝Al-电：橡套电缆产线中拉丝工序电能源消费量，单位kWh M线缆-橡套电缆-拉丝Al:橡套电缆产线中拉丝工序铝产量，单位为t | H35: kWh/t | I35: 集控 | J35: 关键工序 | K35: 电装管理要求 | N35: ①橡套电缆产线拉丝工序耗电量 / ②对应耗铝量 | O35: EN-021、OUT-008 | P35: 采集拉丝（铝）设备的电耗，统计耗铝量，上送电装集控中心。
A36: 35 | B36: IND-035 | C36: 单位产量能耗（变压器-特高压-器身干燥） | D36: 关键工序管控指标（分产业设置，管控能耗较高的工序） | E36: 变压器特高压产线器身干燥工序每万kVA综合能耗 | F36: e变-特高压-器身干燥 = E变-特高压-器身干燥 / M变-特高压-器身干燥 | G36: 月度指标。 e变-特高压-器身干燥:变压器特高压产线器身干燥工序单位产品能耗，单位为tce/万kVA； E变-特高压-器身干燥：变压器特高压产线器身干燥工序综合能源消费量，单位tce M变-特高压-器身干燥:变压器特高压产线器身干燥工序产品产量，单位为万kVA | H36: tce/万kVA | I36: 集控 | J36: 关键工序 | K36: 电装管理要求 | M36: 沈变本部、衡变本部、新变超高压公司 | N36: ①变压器特高压产线器身干燥工序耗电量、蒸汽消耗量 / ②对应变压器产量。 | O36: EN-025、OUT-008 | P36: 采集器身干燥设备的电耗、蒸汽消耗。统计对应变压器产量，上送电装集控中心。
A37: 36 | B37: IND-036 | C37: 单位产量电耗（变压器-特高压-器身干燥） | D37: 关键工序管控指标（分产业设置，管控能耗较高的工序） | E37: 变压器特高压产线器身干燥工序每万kVA电耗 | F37: q变-特高压-器身干燥-电 = Q变-特高压-器身干燥-电 / M变-特高压-器身干燥 | G37: 月度指标 q变-特高压-器身干燥-电：变压器特高压产线器身干燥工序中单位产品电耗，单位为kWh/万kVA； Q变-特高压-器身干燥-电：变压器特高压产线器身干燥工序中电能源消费量，单位kWh M变-特高压-器身干燥:变压器特高压产线器身干燥工序产品产量，单位为万kVA | H37: kWh/万kVA | I37: 集控 | J37: 关键工序 | K37: 电装管理要求 | N37: ①变压器特高压产线器身干燥工序耗电量 / ②对应变压器产量。 | O37: EN-021、OUT-008
A38: 37 | B38: IND-037 | C38: 单位产量蒸汽耗（变压器-特高压-器身干燥） | D38: 关键工序管控指标（分产业设置，管控能耗较高的工序） | E38: 变压器特高压产线器身干燥工序每万kVA蒸汽耗 | F38: q变-特高压-器身干燥-蒸汽 = Q变-特高压-器身干燥-蒸汽 / M变-特高压-器身干燥 | G38: 月度指标 q变-特高压-器身干燥-蒸汽：变压器特高压产线器身干燥工序中单位产品蒸汽耗，单位为t/万kVA； Q变-特高压-器身干燥-蒸汽：变压器特高压产线器身干燥工序中蒸汽能源消费量，单位t M变-特高压-器身干燥:变压器特高压产线器身干燥工序产品产量，单位为万kVA | H38: t/万kVA | I38: 集控 | J38: 关键工序 | K38: 电装管理要求 | N38: ①变压器特高压产线器身干燥工序蒸汽消耗量 / ②对应变压器产量。 | O38: EN-022、OUT-008
A39: 38 | B39: IND-038 | C39: 单位产量能耗（变压器-特高压-试验） | D39: 关键工序管控指标（分产业设置，管控能耗较高的工序） | E39: 变压器特高压产线试验工序每万kVA综合能耗 | F39: e变-特高压-试验 = E变-特高压-试验 / M变-特高压-试验 | G39: 月度指标。 e变-特高压-试验:变压器特高压产线试验工序单位产品能耗，单位为tce/万kVA； E变-特高压-试验：变压器特高压产线试验工序综合能源消费量，单位tce M变-特高压-试验:变压器特高压产线试验工序产品产量，单位为万kVA | H39: tce/万kVA | I39: 集控 | J39: 关键工序 | K39: 电装管理要求 | N39: ①变压器特高压产线试验工序耗电量 / ②对应变压器产量。 | O39: EN-025、OUT-008 | P39: 采集试验设备的电耗。统计对应变压器产量，上送电装集控中心。
A40: 39 | B40: IND-039 | C40: 单位产量电耗（变压器-特高压-试验） | D40: 关键工序管控指标（分产业设置，管控能耗较高的工序） | E40: 变压器特高压产线试验工序每万kVA电耗 | F40: q变-特高压-试验-电 = Q变-特高压-试验-电 / M变-特高压-试验 | G40: 月度指标 q变-特高压-试验-电：变压器特高压产线试验工序中单位产品电耗，单位为kWh/万kVA； Q变-特高压-试验-电：变压器特高压产线试验工序中电能源消费量，单位kWh M变-特高压-试验:变压器特高压产线试验工序产品产量，单位为万kVA | H40: kWh/万kVA | I40: 集控 | J40: 关键工序 | K40: 电装管理要求 | O40: EN-021、OUT-008
...

Sheet 04-公式变量映射
A1: 指标编码 | B1: 指标名称 | C1: 变量序号 | D1: 变量符号 | E1: 变量含义 | F1: 变量角色 | G1: 对应参数编码 | H1: 变量单位 | I1: 原表变量定义
A2: IND-001 | B2: 产品碳足迹 | C2: 0 | D2: — | E2: 无显式变量，按外部标准方法核算 | F2: 指标值（被计算量） | G2: IND-001 | H2: tCo2/台套，tCo2/km等 | I2: 实时数据，产品碳足迹值
A3: IND-002 | B3: 开展产品碳足迹分析占比 | C3: 1 | D3: Rcf | E3: 开展产品碳足迹分析占比 | F3: 指标值（被计算量） | G3: IND-002 | H3: % | I3: 开展产品碳足迹分析占比
A4: IND-002 | B4: 开展产品碳足迹分析占比 | C4: 2 | D4: Ncf | E4: 开展主要产品碳足迹分析的产品类别数量 | F4: 分子 ｜ 开展碳足迹分析的产品类别数量 | G4: CAR-010 | H4: 个 | I4: 开展主要产品碳足迹分析的产品类别数量
A5: IND-002 | B5: 开展产品碳足迹分析占比 | C5: 3 | D5: N | E5: 主要产品类别总数 | F5: 分母 ｜ 主要产品类别总数 | G5: CAR-011 | H5: 个 | I5: 主要产品类别总数
A6: IND-003 | B6: 综合能源消费量 | C6: 1 | D6: E | E6: 综合能源消耗量 | F6: 指标值（被计算量） | G6: IND-003 | H6: tce | I6: 综合能源消耗量，单位为tce
A7: IND-003 | B7: 综合能源消费量 | C7: 2 | D7: n | E7: 消耗的能源种类数 | F7: 维度（能源品种计数） | G7: EN-014 | H7: 个 | I7: 消耗的能源种类数
A8: IND-003 | B8: 综合能源消费量 | C8: 3 | D8: Ei | E8: 实际消耗的第i种能源量 | F8: 因子（分品种能源消费量） | G8: EN-015 | H8: 各品种原单位 | I8: 实际消耗的第i种能源量
A9: IND-003 | B9: 综合能源消费量 | C9: 4 | D9: ki | E9: 第i种能源的折标准煤系数 | F9: 系数（分品种折标准煤系数） | G9: EN-016 | H9: kgce/单位或 tce/单位 | I9: 第i种能源的折标准煤系数
A10: IND-004 | B10: 总碳排放量 | C10: 1 | D10: C | E10: 二氧化碳排放量 | F10: 指标值（被计算量） | G10: IND-004 | H10: 吨二氧化碳（tCO2） | I10: 二氧化碳排放量，单位为吨二氧化碳（tCO2）
A11: IND-004 | B11: 总碳排放量 | C11: 2 | D11: C燃烧 | E11: 化石燃料燃烧产生的二氧化碳排放量总和 | F11: 加项（化石燃料燃烧排放量） | G11: CAR-002 | H11: 吨二氧化碳（tCO2） | I11: 化石燃料燃烧产生的二氧化碳排放量总和，单位为吨二氧化碳（tCO2）
A12: IND-004 | B12: 总碳排放量 | C12: 3 | D12: C过程 | E12: 过程二氧化碳排放量总和 | F12: 加项（过程排放量） | G12: CAR-003 | H12: 吨二氧化碳（tCO2） | I12: 过程二氧化碳排放量总和，单位为吨二氧化碳（tCO2）
A13: IND-004 | B13: 总碳排放量 | C13: 4 | D13: C购入电 | E13: 购入的电力所产生的二氧化碳排放 | F13: 加项（购入电力排放量） | G13: CAR-004 | H13: 吨二氧化碳（tCO2） | I13: 购入的电力所产生的二氧化碳排放，单位为吨二氧化碳（tCO2）
... A285: IND-094 | B285: 单位产量电耗（硅钢铁心-大型叠装） | C285: 3 | D285: M硅钢-大型叠装 | E285: 硅钢铁心大型叠装工序产品产量 | F285: 分母 ｜ 工序 / 产品产量（通用） | G285: OUT-008 | H285: t | I285: 硅钢铁心大型叠装工序产品产量，单位为t

Sheet 05-数据源清单
A1: 来源编码 | B1: 数据源系统 | C1: 归属方 | D1: 提供数据内容 | E1: 对接方式 | F1: 更新频率 | G1: 责任方 | H1: 备注
A2: SRC-01 | B2: 集控中心（能碳管控平台） | C2: 电装（集团） | D2: 各能源品种计量数据、能耗指标计算结果、手工录入数据（绿电 / 绿证、工业增加值、用水量、装备台账） | E2: 平台内部 | F2: 实时 / 月度 | G2: 电装信息化 | H2: 指标计算与展示主平台，集控类指标的权威数据源
A3: SRC-02 | B3: 碳足迹在线核算及报告系统 | C3: 电装（集团） | D3: 产品碳足迹值、开展碳足迹分析的产品种类明细、生产-能源绑定关系 | E3: 系统对接 | F3: 实时 / 月度 | G3: 电装 | H3: 支撑 IND-001、IND-002，并回流绑定关系至集控中心
A4: SRC-03 | B4: 本地数据采集模块 | C4: 各项目公司 | D4: 关键工序、车间用能数据（电 / 蒸汽 / 天然气 / 热力） | E4: 边缘采集 → 集控中心 | F4: 实时 | G4: 各项目公司 | H4: 工序级指标的唯一数据入口，需完成部署与联调
A5: SRC-04 | B5: ERP 系统 | C5: 各项目公司 | D5: 产品型号、产品种类、订单产量、入库公里数与截面、物料数据、生产工单、主要产品类别总数 | E5: 标准接口 | F5: 日 / 月度 | G5: 各项目公司 / 电装信息化 | H5: 产量与产品主数据的来源
A6: SRC-05 | B6: MES 系统 | C6: 部分项目公司 | D6: 生产工单、工序产量、工序产值（如 GIS 抽真空 / 干燥 / 试验 / 除湿工序产值） | E6: 标准接口 | F6: 日 / 月度 | G6: 各项目公司 | H6: —
A7: SRC-06 | B7: 电装大数据平台 | C7: 电装（集团） | D7: 线缆产值（颗粒度到产线） | E7: 系统对接 | F7: 日更新 | G7: 电装 | H7: IND-010 单位产值能耗的分母来源之一
A8: SRC-07 | B8: 经营日报管理系统 | C8: 各项目公司 | D8: 变压器产值（颗粒度到项目公司） | E8: 系统对接 | F8: 日更新 | G8: 各项目公司 | H8: IND-010 单位产值能耗的分母来源之一
A9: SRC-08 | B9: 集团主数据管理系统 | C9: 集团 | D9: 组织主数据（经营单位 / 项目公司编码与名称、产业分类） | E9: 系统对接 | F9: 变更时同步 | G9: 集团 / 电装信息化 | H9: 组织维度的统一口径
A10: SRC-09 | B10: 集控中心录入界面 | C10: 各项目公司 | D10: 绿电 / 绿证量、天然气 / 柴油 / 汽油 / 煤油（无法自动采集时）、工业增加值、用水量、节能装备台账 | E10: 手工录入 | F10: 月度 / 增量更新 | G10: 各项目公司 | H10: 自动采集不覆盖项的手工兜底通道
A11: SRC-10 | B11: 省级电网 / 生态环境主管部门公布口径 | C11: 外部 | D11: 省级电力平均二氧化碳排放因子、所在省平均发电煤耗 | E11: 外部引用 | F11: 年度 | G11: 电装 | H11: 计算系数（FAC-002、FAC-009）的维护依据

Sheet 06-枚举字典
A1: 字典编码 | B1: 字典名称 | C1: 枚举值 | D1: 字典说明 | E1: 适用字段 | F1: 备注
A2: ORG-01 | B2: 经营单位 | C2: 沈变 | D2: 集团下 6 家经营单位（产业板块级） | E2: ORG-001 经营单位编码 / ORG-002 经营单位名称 | F2: 各经营单位下辖多个项目公司
A3: ORG-01 | B3: 经营单位 | C3: 衡变 | D3: 集团下 6 家经营单位（产业板块级） | E3: ORG-001 经营单位编码 / ORG-002 经营单位名称 | F3: 各经营单位下辖多个项目公司
A4: ORG-01 | B4: 经营单位 | C4: 新变 | D4: 集团下 6 家经营单位（产业板块级） | E4: ORG-001 经营单位编码 / ORG-002 经营单位名称 | F4: 各经营单位下辖多个项目公司
A5: ORG-01 | B5: 经营单位 | C5: 鲁缆 | D5: 集团下 6 家经营单位（产业板块级） | E5: ORG-001 经营单位编码 / ORG-002 经营单位名称 | F5: 各经营单位下辖多个项目公司
A6: ORG-01 | B6: 经营单位 | C6: 德缆 | D6: 集团下 6 家经营单位（产业板块级） | E6: ORG-001 经营单位编码 / ORG-002 经营单位名称 | F6: 各经营单位下辖多个项目公司
A7: ORG-01 | B7: 经营单位 | C7: 新缆 | D7: 集团下 6 家经营单位（产业板块级） | E7: ORG-001 经营单位编码 / ORG-002 经营单位名称 | F7: 各经营单位下辖多个项目公司
A8: ORG-02 | B8: 项目公司 | C8: 沈变：沈变本部、和新套管、康嘉互感器 | D8: 各经营单位下属项目公司清单（指标覆盖范围与上报主体） | E8: ORG-003 项目公司编码 / ORG-004 项目公司名称 | F8: 原表覆盖范围列口径，共 6 家经营单位、22 个项目公司
A9: ORG-02 | B9: 项目公司 | C9: 衡变：衡变本部、南京电研、云集电气、湖南电气、云集高压开关、新疆自控、特能建、合容电气、赛杰爱迪 | D9: 各经营单位下属项目公司清单（指标覆盖范围与上报主体） | E9: ORG-003 项目公司编码 / ORG-004 项目公司名称 | F9: 原表覆盖范围列口径，共 6 家经营单位、22 个项目公司
A10: ORG-02 | B10: 项目公司 | C10: 新变：新变超高压公司、新变天变公司、新变智能电气、新变京津冀智能科技、珠峰硅钢 | D10: 各经营单位下属项目公司清单（指标覆盖范围与上报主体） | E10: ORG-003 项目公司编码 / ORG-004 项目公司名称 | F10: 原表覆盖范围列口径，共 6 家经营单位、22 个项目公司
A11: ORG-02 | B11: 项目公司 | C11: 鲁缆：鲁缆本部、曙光公司 | D11: 各经营单位下属项目公司清单（指标覆盖范围与上报主体） | E11: ORG-003 项目公司编码 / ORG-004 项目公司名称 | F11: 原表覆盖范围列口径，共 6 家经营单位、22 个项目公司
A12: ORG-02 | B12: 项目公司 | C12: 德缆：德缆公司 | D12: 各经营单位下属项目公司清单（指标覆盖范围与上报主体） | E12: ORG-003 项目公司编码 / ORG-004 项目公司名称 | F12: 原表覆盖范围列口径，共 6 家经营单位、22 个项目公司
... A136: DM-05 | B136: 必填标识 | C136: 否 | D136: 参数在指标计算中是否必须提供 | E136: 基础参数表.必填 | F136: 非必填参数仅在对应指标启用时录入
