Workbook

Sheet 01-说明与查询
A1: 「双中心」项目能碳管控平台 · 基础参数与指标字典 V2.2
A2: 指标参数构成展开版 | 数据来源：《“双中心”项目能碳管控指标体系（9.16）V1.7》、《“双中心”数据需求清单9.16》、《“双中心”数据需求清单V1.0 (8.27)》 | 适用范围：电装零碳集控中心 + 产品碳足迹集采中心
A4: 【一】参数 / 数据项速查
A5: 在下方黄色单元格输入【参数编码】或【参数名称】（点右侧下拉可选取全部 426 项），下方自动返回数据说明、来源、格式等全部属性；若该参数是复合参数（如「综合能源消费量」），还会返回它由哪些分项折算而来。
A6: ① 输入参数编码 / 名称 | B6: EN-KE46
A7: ② 匹配行号（辅助列） | B7: {==IF($B$6="","",IFERROR(MATCH($B$6,'02-基础参数表'!$B:$B,0),IFERROR(MATCH($B$6,'02-基础参数表'!$C:$C,0),"")))} -> 244
A9: 属性 | B9: 取值
A10: 参数编码 | B10: {==IF($B$7="","",IFERROR(INDEX('02-基础参数表'!$B:$Y,$B$7,1),""))} -> EN-KE46
A11: 参数名称 | B11: {==IF($B$7="","",IFERROR(INDEX('02-基础参数表'!$B:$Y,$B$7,2),""))} -> 工序电力消费量（线缆-导线-拉丝·铜）
A12: 颗粒度层级 | B12: {==IF($B$7="","",IFERROR(INDEX('02-基础参数表'!$B:$Y,$B$7,3),""))} -> 工序级
A13: 数据类型 | B13: {==IF($B$7="","",IFERROR(INDEX('02-基础参数表'!$B:$Y,$B$7,4),""))} -> 实测值
A14: 变量符号（原表） | B14: {==IF($B$7="","",IFERROR(INDEX('02-基础参数表'!$B:$Y,$B$7,5),""))} -> Q线缆-导线-拉丝Cu-电
A15: 所属产线 | B15: {==IF($B$7="","",IFERROR(INDEX('02-基础参数表'!$B:$Y,$B$7,6),""))} -> 线缆-导线
A16: 所属工序 | B16: {==IF($B$7="","",IFERROR(INDEX('02-基础参数表'!$B:$Y,$B$7,7),""))} -> 拉丝
A17: 数据类别 | B17: {==IF($B$7="","",IFERROR(INDEX('02-基础参数表'!$B:$Y,$B$7,8),""))} -> 能源数据
A18: 数据说明 | B18: {==IF($B$7="","",IFERROR(INDEX('02-基础参数表'!$B:$Y,$B$7,9),""))} -> 导线产线中拉丝工序电力消费量（计量对象：铜）。
A19: 单位 | B19: {==IF($B$7="","",IFERROR(INDEX('02-基础参数表'!$B:$Y,$B$7,10),""))} -> kWh
A20: 数据格式 | B20: {==IF($B$7="","",IFERROR(INDEX('02-基础参数表'!$B:$Y,$B$7,11),""))} -> 数值（0 位小数）
A21: 小数位 | B21: {==IF($B$7="","",IFERROR(INDEX('02-基础参数表'!$B:$Y,$B$7,12),""))} -> 0
A22: 取值范围 | B22: {==IF($B$7="","",IFERROR(INDEX('02-基础参数表'!$B:$Y,$B$7,13),""))} -> ≥ 0，≤ 该产线总电量
A23: 默认值 | B23: {==IF($B$7="","",IFERROR(INDEX('02-基础参数表'!$B:$Y,$B$7,14),""))} -> —
A24: 数据来源 | B24: {==IF($B$7="","",IFERROR(INDEX('02-基础参数表'!$B:$Y,$B$7,15),""))} -> 能源计量系统 / 产线工序电表
A25: 来源字段 / 表 | B25: {==IF($B$7="","",IFERROR(INDEX('02-基础参数表'!$B:$Y,$B$7,16),""))} -> 能源计量系统.产线-工序计量点.正向有功电量累计值
A26: 获取方式 | B26: {==IF($B$7="","",IFERROR(INDEX('02-基础参数表'!$B:$Y,$B$7,17),""))} -> 自动采集
A27: 采集 / 更新频率 | B27: {==IF($B$7="","",IFERROR(INDEX('02-基础参数表'!$B:$Y,$B$7,18),""))} -> 月度
A28: 是否必填 | B28: {==IF($B$7="","",IFERROR(INDEX('02-基础参数表'!$B:$Y,$B$7,19),""))} -> 是
A29: 责任单位 | B29: {==IF($B$7="","",IFERROR(INDEX('02-基础参数表'!$B:$Y,$B$7,20),""))} -> 各项目公司能源管理岗
A30: 关联指标编码 | B30: {==IF($B$7="","",IFERROR(INDEX('02-基础参数表'!$B:$Y,$B$7,21),""))} -> IND-017（吨铜电耗（线缆-导线-拉丝））
A31: ▶ 指标构成 / 参数构成（细分项） | B31: {==IF($B$7="","",IFERROR(INDEX('02-基础参数表'!$B:$Y,$B$7,22),""))} -> —
A32: 校验规则 | B32: {==IF($B$7="","",IFERROR(INDEX('02-基础参数表'!$B:$Y,$B$7,23),""))} -> 非负、与计量点绑定、按月累计、单位 kWh
A33: 备注 | B33: {==IF($B$7="","",IFERROR(INDEX('02-基础参数表'!$B:$Y,$B$7,24),""))} -> 颗粒度：产线「线缆-导线」× 工序「拉丝」× 物料「铜」。原表变量符号「Q线缆-导线-拉丝Cu-电」。
A35: 【二】指标速查
A36: 输入【指标编码】或【指标名称】，自动返回该指标的规范计算公式、所需的最小颗粒度数据项编码，以及构成该指标的全部参数细分项（分子 / 分母 / 加项 / 扣减项），可直接据此取数。
A37: ① 输入指标编码 / 名称 | B37: IND-017
A38: ② 匹配行号（辅助列） | B38: {==IF($B$37="","",IFERROR(MATCH($B$37,'03-指标清单'!$A:$A,0),IFERROR(MATCH($B$37,'03-指标清单'!$B:$B,0),"")))} -> 18
A40: 属性 | B40: 取值
A41: 指标编码 | B41: {==IF($B$38="","",IFERROR(INDEX('03-指标清单'!$A:$S,$B$38,1),""))} -> IND-017
A42: 指标名称 | B42: {==IF($B$38="","",IFERROR(INDEX('03-指标清单'!$A:$S,$B$38,2),""))} -> 吨铜电耗（线缆-导线-拉丝）
A43: 指标体系 | B43: {==IF($B$38="","",IFERROR(INDEX('03-指标清单'!$A:$S,$B$38,3),""))} -> 关键工序
A44: 所属中心 | B44: {==IF($B$38="","",IFERROR(INDEX('03-指标清单'!$A:$S,$B$38,4),""))} -> 集控中心
...

Sheet 02-基础参数表
A1: 02 · 基础参数表（统一参数与数据项定义）
A2: 共 426 项 = 公共参数 97（工厂级 / 主数据 / 系数）+ 既有域补充 7（能源品种 / 系数）+ 零碳园区与集控中心数据 85 + 产品级数据项 6 + 工序级数据项 137 + 指标定义 94。颗粒度已拆分到「产线 × 工序 × 介质 / 物料」与「园区 / 设备 / 系统 / 订单」，公式取数请使用最小颗粒度编码。「指标构成 / 参数构成（细分项）」列：指标行写明该指标由哪些参数构成，复合参数行写明它由哪些分项折算而来，可直接据此追溯取数链路。
A3: 序号 | B3: 参数编码 | C3: 参数名称 | D3: 颗粒度层级 | E3: 数据类型 | F3: 变量符号（原表） | G3: 所属产线 | H3: 所属工序 | I3: 数据类别 | J3: 数据说明 | K3: 单位 | L3: 数据格式 | M3: 小数位 | N3: 取值范围 | O3: 默认值 | P3: 数据来源 | Q3: 来源字段 / 表 | R3: 获取方式 | S3: 采集 / 更新频率 | T3: 是否必填 | U3: 责任单位 | V3: 关联指标编码 | W3: 指标构成 / 参数构成（细分项） | X3: 校验规则 | Y3: 备注
A4: 1 | B4: ORG-001 | C4: 经营单位编码 | D4: 组织主数据 | E4: 主数据 | F4: — | I4: 组织主数据 | J4: 集团级经营单位（产业板块）的唯一标识编码，用于全部指标的组织维度归集 | K4: — | L4: 文本 | M4: — | N4: 见「06-枚举字典」ORG-01 | O4: — | P4: 集团主数据管理系统 | Q4: 组织主数据.经营单位编码 | R4: 系统对接 | S4: 变更时同步 | T4: 是 | U4: 集团 / 电装信息化 | V4: 全部指标 | W4: — | X4: 非空、全局唯一 | Y4: 覆盖沈变、衡变、新变、鲁缆、德缆、新缆 6 家经营单位
A5: 2 | B5: ORG-002 | C5: 经营单位名称 | D5: 组织主数据 | E5: 主数据 | F5: — | I5: 组织主数据 | J5: 经营单位中文名称 | K5: — | L5: 文本 | M5: — | N5: 沈变 / 衡变 / 新变 / 鲁缆 / 德缆 / 新缆 | O5: — | P5: 集团主数据管理系统 | Q5: 组织主数据.经营单位名称 | R5: 系统对接 | S5: 变更时同步 | T5: 是 | U5: 集团 / 电装信息化 | V5: 全部指标 | W5: — | X5: 与编码一一对应 | Y5: —
A6: 3 | B6: ORG-003 | C6: 项目公司编码 | D6: 组织主数据 | E6: 主数据 | F6: — | I6: 组织主数据 | J6: 经营单位下属项目公司的唯一标识编码，是集控 / 集采指标的核算与上报主体 | K6: — | L6: 文本 | M6: — | N6: 见「06-枚举字典」ORG-02 | O6: — | P6: 集团主数据管理系统 | Q6: 组织主数据.公司编码 | R6: 系统对接 | S6: 变更时同步 | T6: 是 | U6: 各项目公司 | V6: 全部指标 | W6: — | X6: 非空、全局唯一 | Y6: 共 22 个项目公司（含各产业本部）
A7: 4 | B7: ORG-004 | C7: 项目公司名称 | D7: 组织主数据 | E7: 主数据 | F7: — | I7: 组织主数据 | J7: 项目公司中文名称，如沈变本部、和新套管、康嘉互感器、南京电研等 | K7: — | L7: 文本 | M7: — | N7: 见「06-枚举字典」ORG-02 | O7: — | P7: 集团主数据管理系统 | Q7: 组织主数据.公司名称 | R7: 系统对接 | S7: 变更时同步 | T7: 是 | U7: 各项目公司 | V7: 全部指标 | W7: — | X7: 与编码一一对应 | Y7: —
A8: 5 | B8: ORG-005 | C8: 产业板块 | D8: 组织主数据 | E8: 主数据 | F8: — | I8: 组织主数据 | J8: 项目公司所属产业分类，决定其纳入的指标范围与工序口径 | K8: — | L8: 枚举 | M8: — | N8: 见「06-枚举字典」ORG-03 | O8: — | P8: 集团主数据管理系统 | Q8: 组织主数据.产业分类 | R8: 系统对接 | S8: 变更时同步 | T8: 是 | U8: 集团 / 电装信息化 | V8: 关键工序类指标（IND-017~IND-094） | W8: — | X8: 取值须在枚举内 | Y8: 同一项目公司可归多个板块
A9: 6 | B9: ORG-006 | C9: 生产管理单元编码 | D9: 组织主数据 | E9: 主数据 | F9: — | I9: 组织主数据 | J9: 车间、产线、工段级生产单元编码，是「生产-能源绑定」的原子对象 | K9: — | L9: 文本 | M9: — | N9: — | O9: — | P9: 集控中心 / 碳足迹在线核算及报告系统 | Q9: 生产管理单元主数据 | R9: 系统对接 | S9: 变更时同步 | T9: 是 | U9: 各项目公司 | V9: IND-012~IND-094 | W9: — | X9: 非空、单位内唯一 | Y9: 须与能耗计量点完成绑定
A10: 7 | B10: ORG-007 | C10: 计量点编码 | D10: 组织主数据 | E10: 主数据 | F10: — | I10: 组织主数据 | J10: 能源计量器具 / 测点唯一编码（电表、蒸汽流量计、气表等） | K10: — | L10: 文本 | M10: — | N10: — | O10: — | P10: 集控中心 / 能源管理系统 | Q10: 计量器具台账.测点编号 | R10: 系统对接 | S10: 变更时同步 | T10: 是 | U10: 各项目公司 | V10: 全部能耗类指标 | W10: — | X10: 非空、单位内唯一 | Y10: 采集通道须与测点编号对应
A11: 8 | B11: ORG-008 | C11: 生产管理单元-计量点绑定关系 | D11: 组织主数据 | E11: 主数据 | F11: — | I11: 组织主数据 | J11: 生产管理单元与能源计量点的对应关系（可多对多），是工序能耗拆分与归集的依据 | K11: — | L11: 文本 | M11: — | N11: — | O11: — | P11: 碳足迹在线核算及报告系统 | Q11: 生产-能源绑定模块 | R11: 系统对接 / 手工配置 | S11: 变更时更新 | T11: 是 | U11: 各项目公司 | V11: IND-017~IND-094 | W11: — | X11: 绑定率 100% | Y11: 未绑定将导致工序能耗无法核算
A12: 9 | B12: MD-001 | C12: 产品型号 | D12: 生产主数据 | E12: 主数据 | F12: — | I12: 生产主数据 | J12: 产品规格型号编码，是产品级指标（最小到型号）的统计维度 | K12: — | L12: 文本 | M12: — | N12: — | O12: — | P12: ERP 系统 | Q12: 物料主数据.型号 | R12: 系统对接 | S12: 变更时同步 | T12: 是 | U12: 各项目公司 | V12: IND-012~IND-016 | W12: — | X12: 非空 | Y12: —
A13: 10 | B13: MD-002 | C13: 产品种类（ERP） | D13: 生产主数据 | E13: 主数据 | F13: — | I13: 生产主数据 | J13: ERP 中的产品大类 / 种类编码，用于型号-种类-产线映射 | K13: — | L13: 文本 | M13: — | N13: — | O13: — | P13: ERP 系统 | Q13: 物料主数据.产品种类 | R13: 系统对接 | S13: 变更时同步 | T13: 是 | U13: 各项目公司 | V13: IND-002、IND-012 | W13: — | X13: 非空 | Y13: —
A14: 11 | B14: MD-003 | C14: 产线编码 | D14: 生产主数据 | E14: 主数据 | F14: — | I14: 生产主数据 | J14: 电装产线大类编码（导线、布电线、高压 / 中压 / 低压电缆、特种电缆、装备电缆、橡套电缆、变压器各产线等） | K14: — | L14: 文本 | M14: — | N14: 见「06-枚举字典」MD-01 | O14: — | P14: 集控中心 | Q14: 产线主数据.产线编码 | R14: 系统对接 | S14: 变更时同步 | T14: 是 | U14: 各项目公司 | V14: IND-012~IND-094 | W14: — | X14: 非空、全局唯一 | Y14: —
A15: 12 | B15: MD-004 | C15: 工序编码 | D15: 生产主数据 | E15: 主数据 | F15: — | I15: 生产主数据 | J15: 关键工序编码（拉丝、交联、器身干燥、试验、浇注固化、钣金加工、SMT 贴片、退火、纵剪、叠装等） | K15: — | L15: 文本 | M15: — | N15: 见「06-枚举字典」MD-02 | O15: — | P15: 集控中心 | Q15: 工序主数据.工序编码 | R15: 系统对接 | S15: 变更时同步 | T15: 是 | U15: 各项目公司 | V15: IND-017~IND-094 | W15: — | X15: 非空、与产线对应 | Y15: —
... A198: 195 | B198: EN-P05 | C198: 产品水消费量（型号口径） | D198: 产品级 | E198: 接口值 / 计算值 | F198: Q水 | I198: 能源数据 | J198: 统计期内，归属到「产品型号 × ERP 产品种类 × 电装产线大类」口径的取水量。 | K198: t | L198: 数值（3 位小数） | M198: 3 | N198: ≥ 0 | O198: — | P198: 水务计量系统（按型号分摊后汇总） | Q198: ERP / 能源计量系统（按型号-种类-产线分摊） | R198: 计算 | S198: 月度 | T198: 是 | U198: 各项目公司能源管理岗 | V198: IND-016（单位产品水耗） | W198: — | X198: 非负；须先完成「型号-产品种类-产线」映射（MD-005）与能源分摊 | Y198: 颗粒度：产品型号 × ERP 产品种类 × 电装产线大类。原表变量符号「Q水」。
A199: 196 | B199: EN-KE01 | C199: 工序电力消费量（GIL-测试） | D199: 工序级 | E199: 实测值 | F199: QGIL-测试-电 | G199: GIL | H199: 测试 | I199: 能源数据 | J199: GIL测试工序电力消费量。 | K199: kWh | L199: 数值（0 位小数） | M199: 0 | N199: ≥ 0，≤ 该产线总电量 | O199: — | P199: 能源计量系统 / 产线工序电表 | Q199: 能源计量系统.产线-工序计量点.正向有功电量累计值 | R199: 自动采集 | S199: 月度 | T199: 是 | U199: 各项目公司能源管理岗 | V199: IND-085（单位产值电耗（GIL-测试)） | W199: — | X199: 非负、与计量点绑定、按月累计、单位 kWh | Y199: 颗粒度：产线「GIL」× 工序「测试」。原表变量符号「QGIL-测试-电」。
A200: 197 | B200: EN-KE02 | C200: 工序电力消费量（GIL-绝缘子生产） | D200: 工序级 | E200: 实测值 | F200: QGIL-绝缘-电 | G200: GIL | H200: 绝缘子生产 | I200: 能源数据 | J200: GIL绝缘子生产工序电力消费量。 | K200: kWh | L200: 数值（0 位小数） | M200: 0 | N200: ≥ 0，≤ 该产线总电量 | O200: — | P200: 能源计量系统 / 产线工序电表 | Q200: 能源计量系统.产线-工序计量点.正向有功电量累计值 | R200: 自动采集 | S200: 月度 | T200: 是 | U200: 各项目公司能源管理岗 | V200: IND-086（单位产值电耗（GIL-绝缘子生产)） | W200: — | X200: 非负、与计量点绑定、按月累计、单位 kWh | Y200: 颗粒度：产线「GIL」× 工序「绝缘子生产」。原表变量符号「QGIL-绝缘-电」。
A201: 198 | B201: EN-KE03 | C201: 工序电力消费量（GIL-螺旋焊管生产） | D201: 工序级 | E201: 实测值 | F201: QGIL-螺旋焊管-电 | G201: GIL | H201: 螺旋焊管生产 | I201: 能源数据 | J201: GIL螺旋焊管生产工序电力消费量。 | K201: kWh | L201: 数值（0 位小数） | M201: 0 | N201: ≥ 0，≤ 该产线总电量 | O201: — | P201: 能源计量系统 / 产线工序电表 | Q201: 能源计量系统.产线-工序计量点.正向有功电量累计值 | R201: 自动采集 | S201: 月度 | T201: 是 | U201: 各项目公司能源管理岗 | V201: IND-084（单位产值电耗（GIL-螺旋焊管生产)） | W201: — | X201: 非负、与计量点绑定、按月累计、单位 kWh | Y201: 颗粒度：产线「GIL」× 工序「螺旋焊管生产」。原表变量符号「QGIL-螺旋焊管-电」。
A202: 199 | B202: EN-KE04 | C202: 工序电力消费量（GIS-工频耐压试验） | D202: 工序级 | E202: 实测值 | F202: QGIS-试验-电 | G202: GIS | H202: 工频耐压试验 | I202: 能源数据 | J202: GIS工频耐压试验工序电力消费量。 | K202: kWh | L202: 数值（0 位小数） | M202: 0 | N202: ≥ 0，≤ 该产线总电量 | O202: — | P202: 能源计量系统 / 产线工序电表 | Q202: 能源计量系统.产线-工序计量点.正向有功电量累计值 | R202: 自动采集 | S202: 月度 | T202: 是 | U202: 各项目公司能源管理岗 | V202: IND-089（单位产值电耗（GIS-工频耐压试验)） | W202: — | X202: 非负、与计量点绑定、按月累计、单位 kWh | Y202: 颗粒度：产线「GIS」× 工序「工频耐压试验」。原表变量符号「QGIS-试验-电」。
A203: 200 | B203: EN-KE05 | C203: 工序电力消费量（GIS-抽真空） | D203: 工序级 | E203: 实测值 | F203: QGIS-真空-电 | G203: GIS | H203: 抽真空 | I203: 能源数据 | J203: GIS抽真空工序电力消费量。 | K203: kWh | L203: 数值（0 位小数） | M203: 0 | N203: ≥ 0，≤ 该产线总电量 | O203: — | P203: 能源计量系统 / 产线工序电表 | Q203: 能源计量系统.产线-工序计量点.正向有功电量累计值 | R203: 自动采集 | S203: 月度 | T203: 是 | U203: 各项目公司能源管理岗 | V203: IND-087（单位产值电耗（GIS-抽真空)） | W203: — | X203: 非负、与计量点绑定、按月累计、单位 kWh | Y203: 颗粒度：产线「GIS」× 工序「抽真空」。原表变量符号「QGIS-真空-电」。
A204: 201 | B204: EN-KE06 | C204: 工序电力消费量（GIS-空调恒温除湿） | D204: 工序级 | E204: 实测值 | F204: QGIS-除湿-电 | G204: GIS | H204: 空调恒温除湿 | I204: 能源数据 | J204: GIS空调恒温除湿工序电力消费量。 | K204: kWh | L204: 数值（0 位小数） | M204: 0 | N204: ≥ 0，≤ 该产线总电量 | O204: — | P204: 能源计量系统 / 产线工序电表 | Q204: 能源计量系统.产线-工序计量点.正向有功电量累计值 | R204: 自动采集 | S204: 月度 | T204: 是 | U204: 各项目公司能源管理岗 | V204: IND-090（单位产值电耗（GIS-空调恒温除湿)） | W204: — | X204: 非负、与计量点绑定、按月累计、单位 kWh | Y204: 颗粒度：产线「GIS」× 工序「空调恒温除湿」。原表变量符号「QGIS-除湿-电」。
A205: 202 | B205: EN-KE07 | C205: 工序电力消费量（GIS-绝缘件干燥） | D205: 工序级 | E205: 实测值 | F205: QGIS-干燥-电 | G205: GIS | H205: 绝缘件干燥 | I205: 能源数据 | J205: GIS绝缘件干燥工序电力消费量。 | K205: kWh | L205: 数值（0 位小数） | M205: 0 | N205: ≥ 0，≤ 该产线总电量 | O205: — | P205: 能源计量系统 / 产线工序电表 | Q205: 能源计量系统.产线-工序计量点.正向有功电量累计值 | R205: 自动采集 | S205: 月度 | T205: 是 | U205: 各项目公司能源管理岗 | V205: IND-088（单位产值电耗（GIS-绝缘件干燥)） | W205: — | X205: 非负、与计量点绑定、按月累计、单位 kWh | Y205: 颗粒度：产线「GIS」× 工序「绝缘件干燥」。原表变量符号「QGIS-干燥-电」。
A206: 203 | B206: EN-KE08 | C206: 工序电力消费量（中低压开关柜-钣金加工） | D206: 工序级 | E206: 实测值 | F206: Q柜-加工-电 | G206: 中低压开关柜 | H206: 钣金加工 | I206: 能源数据 | J206: 中低压开关柜钣金加工工序中电力消费量。 | K206: kWh | L206: 数值（0 位小数） | M206: 0 | N206: ≥ 0，≤ 该产线总电量 | O206: — | P206: 能源计量系统 / 产线工序电表 | Q206: 能源计量系统.产线-工序计量点.正向有功电量累计值 | R206: 自动采集 | S206: 月度 | T206: 是 | U206: 各项目公司能源管理岗 | V206: IND-066（单位产值电耗（中低压开关柜-钣金加工）） | W206: — | X206: 非负、与计量点绑定、按月累计、单位 kWh | Y206: 颗粒度：产线「中低压开关柜」× 工序「钣金加工」。原表变量符号「Q柜-加工-电」。
A207: 204 | B207: EN-KE09 | C207: 工序电力消费量（中低压开关柜-钣金喷涂） | D207: 工序级 | E207: 实测值 | F207: Q柜-喷涂-电 | G207: 中低压开关柜 | H207: 钣金喷涂 | I207: 能源数据 | J207: 中低压开关柜钣金喷涂工序中电力消费量。 | K207: kWh | L207: 数值（0 位小数） | M207: 0 | N207: ≥ 0，≤ 该产线总电量 | O207: — | P207: 能源计量系统 / 产线工序电表 | Q207: 能源计量系统.产线-工序计量点.正向有功电量累计值 | R207: 自动采集 | S207: 月度 | T207: 是 | U207: 各项目公司能源管理岗 | V207: IND-067（单位产值电耗（中低压开关柜-钣金喷涂）） | W207: — | X207: 非负、与计量点绑定、按月累计、单位 kWh | Y207: 颗粒度：产线「中低压开关柜」× 工序「钣金喷涂」。原表变量符号「Q柜-喷涂-电」。
A208: 205 | B208: EN-KE10 | C208: 工序电力消费量（二次-SMT贴片） | D208: 工序级 | E208: 实测值 | F208: Q二次-贴片-电 | G208: 二次 | H208: SMT贴片 | I208: 能源数据 | J208: 二次-SMT贴片工序电力消费量。 | K208: kWh | L208: 数值（0 位小数） | M208: 0 | N208: ≥ 0，≤ 该产线总电量 | O208: — | P208: 能源计量系统 / 产线工序电表 | Q208: 能源计量系统.产线-工序计量点.正向有功电量累计值 | R208: 自动采集 | S208: 月度 | T208: 是 | U208: 各项目公司能源管理岗 | V208: IND-075（单位产值电耗（二次-SMT贴片）） | W208: — | X208: 非负、与计量点绑定、按月累计、单位 kWh | Y208: 颗粒度：产线「二次」× 工序「SMT贴片」。原表变量符号「Q二次-贴片-电」。
A209: 206 | B209: EN-KE11 | C209: 工序电力消费量（二次-波峰焊） | D209: 工序级 | E209: 实测值 | F209: Q二次-波峰焊-电 | G209: 二次 | H209: 波峰焊 | I209: 能源数据 | J209: 二次-波峰焊工序电力消费量。 | K209: kWh | L209: 数值（0 位小数） | M209: 0 | N209: ≥ 0，≤ 该产线总电量 | O209: — | P209: 能源计量系统 / 产线工序电表 | Q209: 能源计量系统.产线-工序计量点.正向有功电量累计值 | R209: 自动采集 | S209: 月度 | T209: 是 | U209: 各项目公司能源管理岗 | V209: IND-077（单位产值电耗（二次-波峰焊）） | W209: — | X209: 非负、与计量点绑定、按月累计、单位 kWh | Y209: 颗粒度：产线「二次」× 工序「波峰焊」。原表变量符号「Q二次-波峰焊-电」。
A210: 207 | B210: EN-KE12 | C210: 工序电力消费量（二次-高温老化） | D210: 工序级 | E210: 实测值 | F210: Q二次-高温-电 | G210: 二次 | H210: 高温老化 | I210: 能源数据 | J210: 二次-高温老化工序电力消费量。 | K210: kWh | L210: 数值（0 位小数） | M210: 0 | N210: ≥ 0，≤ 该产线总电量 | O210: — | P210: 能源计量系统 / 产线工序电表 | Q210: 能源计量系统.产线-工序计量点.正向有功电量累计值 | R210: 自动采集 | S210: 月度 | T210: 是 | U210: 各项目公司能源管理岗 | V210: IND-076（单位产值电耗（二次-高温老化）） | W210: — | X210: 非负、与计量点绑定、按月累计、单位 kWh | Y210: 颗粒度：产线「二次」× 工序「高温老化」。原表变量符号「Q二次-高温-电」。
... A335: 332 | B335: VAL-KG19 | C335: 工序产品产值（干式电抗器-试验） | D335: 工序级 | E335: 实测值 | F335: G抗-试验 | G335: 干式电抗器 | H335: 试验 | I335: 产值数据 | J335: 干式电抗器试验工序产品产值。 | K335: 万元 | L335: 数值（2 位小数） | M335: 2 | N335: ≥ 0 | O335: — | P335: ERP 财务 / 生产模块 | Q335: ERP.产值报表.工序归集产值 | R335: 系统接口 | S335: 月度 | T335: 是 | U335: 各项目公司财务岗 | V335: IND-083（单位产值电耗（干式电抗器-试验）） | W335: — | X335: 非负、口径与产量一致、按月归集 | Y335: 颗粒度：产线「干式电抗器」× 工序「试验」。原表变量符号「G抗-试验」。
A336: 333 | B336: IND-001 | C336: 产品碳足迹 | D336: 指标·整体指标 | E336: 指标值 | I336: 指标 / 整体指标 | J336: 引用GB/T 24067、ISO14067，主要管理摇篮到大门阶段的产品碳足迹。 | K336: tCo2/台套，tCo2/km等 | L336: 数值 | M336: — | N336: — | O336: — | P336: 外部要求（应对CBAM及绿色招采) | Q336: 由基础数据项按公式计算 | R336: 系统自动计算 | S336: 产品 | T336: — | U336: 电装集采中心 | V336: 由本指标公式决定 | W336: 源表未给出可计算的输入参数，须按 GB/T 24067 / ISO 14067 方法另建核算模型（涉及原材料消耗、各类排放因子等），建议单独出具碳足迹核算附表。 | X336: 见「03-指标清单」 | Y336: —
A337: 334 | B337: IND-002 | C337: 开展产品碳足迹分析占比 | D337: 指标·整体指标 | E337: 指标值 | I337: 指标 / 整体指标 | J337: 指统计期内开展主要产品碳足迹分析的产品类别数量占主要产品类别总数的比值 | K337: % | L337: 数值 | M337: — | N337: — | O337: — | P337: 国家级零碳工厂 | Q337: 由基础数据项按公式计算 | R337: 系统自动计算 | S337: 工厂 | T337: — | U337: 电装集采中心 | V337: 由本指标公式决定 | W337: 分子 · CAR-010 开展碳足迹分析的产品类别数量（个） ｜ 分母 · CAR-011 主要产品类别总数（个） | X337: 见「03-指标清单」 | Y337: Rcf：开展产品碳足迹分析占比；；Ncf:开展主要产品碳足迹分析的产品类别数量;；N:主要产品类别总数
A338: 335 | B338: IND-003 | C338: 综合能源消费量 | D338: 指标·整体指标 | E338: 指标值 | I338: 指标 / 整体指标 | J338: 指统计期内组织综合能源消费的总吨标准煤 | K338: tce | L338: 数值 | M338: — | N338: — | O338: — | P338: 国家级零碳工厂 | Q338: 由基础数据项按公式计算 | R338: 系统自动计算 | S338: 工厂 | T338: — | U338: 电装集控中心 | V338: 由本指标公式决定 | W338: 维度 · EN-014 消耗的能源种类数（个） ｜ 因子 · EN-015 第 i 种能源消费量（各品种原单位） ｜ 系数 · EN-016 第 i 种能源折标准煤系数（kgce/单位或 tce/单位） | X338: 见「03-指标清单」 | Y338: E：综合能源消耗量，单位为tce；n：消耗的能源种类数；Ei:实际消耗的第i种能源量；ki:第i种能源的折标准煤系数
A339: 336 | B339: IND-004 | C339: 总碳排放量 | D339: 指标·整体指标 | E339: 指标值 | I339: 指标 / 整体指标 | J339: 指统计期内企业组织产生的二氧化碳总排放量 | K339: tCO2 | L339: 数值 | M339: — | N339: — | O339: — | P339: 国家级零碳工厂 | Q339: 由基础数据项按公式计算 | R339: 系统自动计算 | S339: 工厂 | T339: — | U339: 电装集控中心 | V339: 由本指标公式决定 | W339: 加项 · CAR-002 化石燃料燃烧排放量（tCO2） ｜ 加项 · CAR-003 过程排放量（tCO2） ｜ 加项 · CAR-004 购入电力排放量（tCO2） ｜ 扣减项 · CAR-005 输出电力排放量（tCO2） ｜ 加项 · CAR-006 购入热力排放量（tCO2） ｜ 扣减项 · CAR-007 输出热力排放量（tCO2） ｜ 扣减项 · CAR-008 二氧化碳回收利用量（tCO2） | X339: 见「03-指标清单」 | Y339: C：二氧化碳排放量，单位为吨二氧化碳（tCO2）；；C燃烧：化石燃料燃烧产生的二氧化碳排放量总和，单位为吨二氧化碳（tCO2）；C过程：过程二氧化碳排放量总和，单位为吨二氧化碳（tCO2）；C购入电：购入的电力所产生的二氧化碳排放，单位为吨二氧化碳（tCO2）；C输出电：输出的电力所产生的二氧化碳排放，单位为吨二氧化碳（tCO2）；C购入热：购入的热力所产生的二氧化碳排放，单位为吨二氧化碳（tCO2）；C输出热：输出的热力所产生的二氧化碳排放，单位为吨二氧化碳（tCO2）；C回收利用：化石燃料燃烧、工艺过程产生的二氧化碳经回收作为生产原料自用或作为产品外供并确保未再次排放所对应的二氧化碳排放量，单位为吨二氧化碳（tCO2）
A340: 337 | B340: IND-005 | C340: 单位能耗碳排放 | D340: 指标·整体指标 | E340: 指标值 | I340: 指标 / 整体指标 | J340: 指统计期内每消费一吨标准煤产生的二氧化碳排放量 | K340: tCO2/tce | L340: 数值 | M340: — | N340: — | O340: — | P340: 国家级零碳工厂 | Q340: 由基础数据项按公式计算 | R340: 系统自动计算 | S340: 工厂 | T340: — | U340: 电装集控中心 | V340: 由本指标公式决定 | W340: 分子 · CAR-001 二氧化碳排放量（tCO2） ｜ 分母 · EN-013 综合能源消费量（tce） | X340: 见「03-指标清单」 | Y340: I:单位能耗碳排放；C：二氧化碳排放量，单位为tCO2；E：综合能源消耗量，单位为tce
A341: 338 | B341: IND-006 | C341: 非化石能源消费占比 | D341: 指标·整体指标 | E341: 指标值 | I341: 指标 / 整体指标 | J341: 指统计期内非化石能源消费量与综合能源消费量的比值 | K341: % | L341: 数值 | M341: — | N341: — | O341: — | P341: 国家级零碳工厂 | Q341: 由基础数据项按公式计算 | R341: 系统自动计算 | S341: 工厂 | T341: — | U341: 电装集控中心 | V341: 由本指标公式决定 | W341: 分子 · EN-019 非化石能源消费量（不含原料用能）（tce） ｜ 分母 · EN-018 综合能源消费量（不含原料用能）（tce） | X341: 见「03-指标清单」 | Y341: r：非化石能源消费占比；R:各类非化石能源消费量(不含作为原料使用的能源)，单位为tce；E:综合能源消费量（不含作为原料使用的能源）,单位为tce
A342: 339 | B342: IND-007 | C342: 非化石能源电力消费物理认定量占比 | D342: 指标·整体指标 | E342: 指标值 | I342: 指标 / 整体指标 | J342: 指统计期内具备物理可溯源条件的非化石能源电力消费量占同期总用电量的比值。 | K342: % | L342: 数值 | M342: — | N342: — | O342: — | P342: 国家级零碳工厂 | Q342: 由基础数据项按公式计算 | R342: 系统自动计算 | S342: 工厂 | T342: — | U342: 电装集控中心 | V342: 由本指标公式决定 | W342: 分子 · EN-005 非化石能源电力消费物理认定量（kWh） ｜ 分母 · EN-020 总用电量（kWh） | X342: 见「03-指标清单」 | Y342: Eui:非化石能源电力消费物理认定量占比；；Ez:具备物理可溯源条件的非化石能源电力消费量，单位为kWh;；Q:总用电量，单位为千kWh
A343: 340 | B343: IND-008 | C343: 单位工业增加值能耗 | D343: 指标·整体指标 | E343: 指标值 | I343: 指标 / 整体指标 | J343: 指统计期内综合能源消费量与工业增加值的比值 | K343: tce/万元 | L343: 数值 | M343: — | N343: — | O343: — | P343: 国家级零碳工厂 | Q343: 由基础数据项按公式计算 | R343: 系统自动计算 | S343: 工厂 | T343: — | U343: 电装集控中心 | V343: 由本指标公式决定 | W343: 分子 · EN-013 综合能源消费量（tce） ｜ 分母 · VAL-001 工业增加值（万元） | X343: 见「03-指标清单」 | Y343: Enva:单位工业增加值能耗，单位为tce/万元；；E：综合能源消费量，单位tce；Gnva:工业增加值，单位为万元
A344: 341 | B344: IND-009 | C344: 节能装备应用占比 | D344: 指标·整体指标 | E344: 指标值 | I344: 指标 / 整体指标 | J344: 指统计期内达到或优于能效强制性国家标准 2 级水平和《重点用能产品设备能效先进水平、节能水平和准入水平》节能水平的装备累计额定总功率占纳入统计范围装备累计额定总功率的比例 | K344: % | L344: 数值 | M344: — | N344: — | O344: — | P344: 国家级零碳工厂 | Q344: 由基础数据项按公式计算 | R344: 系统自动计算 | S344: 工厂 | T344: — | U344: 电装集控中心 | V344: 由本指标公式决定 | W344: 分子 · EQ-001 节能装备累计额定总功率（kW） ｜ 分母 · EQ-002 纳入统计范围装备累计额定总功率（kW） | X344: 见「03-指标清单」 | Y344: S：节能装备应用占比；；Res:达到或优于能效强制性国家标准 2 级水平和《重点用能产品设备能效先进水平、节能水平和准入水平》节能水平的装备累计额定总功率，单位为kW。；Ets:纳入统计范围装备累计额定总功率，单位为kW。纳入统计范围的装备需有适用的能效强制性国家标准，包括但不限于电动机、变压器、工业锅炉、风机、容积式空气压缩机、工业制冷设备、热泵等；无适用标准的装备不纳入统计。
A345: 342 | B345: IND-010 | C345: 单位产值能耗 | D345: 指标·整体指标 | E345: 指标值 | I345: 指标 / 整体指标 | J345: 指统计期内综合能源消费量与产品产值的比值 | K345: tce/万元 | L345: 数值 | M345: — | N345: — | O345: — | P345: 股份管理要求 | Q345: 由基础数据项按公式计算 | R345: 系统自动计算 | S345: 工厂 | T345: — | U345: 电装集控中心 | V345: 由本指标公式决定 | W345: 分子 · EN-013 综合能源消费量（tce） ｜ 分母 · VAL-002 产品产值（万元） | X345: 见「03-指标清单」 | Y345: g:单位产值能耗，单位为tce/万元；；E：综合能源消费量，单位tce；G:产品产值，单位为万元
A346: 343 | B346: IND-011 | C346: 水资源消耗量 | D346: 指标·整体指标 | E346: 指标值 | I346: 指标 / 整体指标 | J346: 指企业在一定时期内，实际用于生产、生活等用途中未返回环境或未再次回用的水量 | K346: t | L346: 数值 | M346: — | N346: — | O346: — | P346: ESG要求 | Q346: 由基础数据项按公式计算 | R346: 系统自动计算 | S346: 工厂 | T346: — | U346: 电装集控中心 | V346: 由本指标公式决定 | W346: 参数 · EN-026 用水量（总量）（t） | X346: 见「03-指标清单」 | Y346: —
...

Sheet 03-指标清单
A1: 指标编码 | B1: 指标名称 | C1: 指标体系 | D1: 所属中心 | E1: 指标层级 | F1: 指标定义 | G1: 规范计算公式（按参数编码） | H1: 最小颗粒度输入项 | I1: 指标说明（原表） | J1: 指标单位 | K1: 指标类别 | L1: 指标来源 | M1: 指标用途 | N1: 覆盖范围 | O1: 所需各单位数据 | P1: 各单位所需开展工作 | Q1: 依赖基础参数 | R1: 开发实现要点 | S1: 参数构成（细分项）
A2: IND-001 | B2: 产品碳足迹 | C2: 整体指标 | D2: 集采中心 | E2: 产品 | F2: 引用GB/T 24067、ISO14067，主要管理摇篮到大门阶段的产品碳足迹。 | G2: 按 GB/T 24067、ISO 14067 方法核算（摇篮到大门） | H2: — | I2: 实时数据，产品碳足迹值 | J2: tCo2/台套，tCo2/km等 | K2: 产品 | L2: 外部要求（应对CBAM及绿色招采) | M2: 自动计算，减少收资，快速应对客户招采对碳足迹的要求 | N2: 沈变：沈变本部、和新套管、康嘉互感器 衡变：本部、南京电研、云集电气、湖南电气、云集高压开关、新疆自控、特能建、合容电气、赛杰爱迪 新变：超高压公司、天变公司、智能电气、京津冀智能科技、珠峰硅钢 鲁缆：鲁缆本部、曙光公司 德缆：德缆 新缆：新疆电缆公司、新疆线缆厂 | O2: 生产工单、物料、能耗数据。 | P2: 各项目公司部署电装下发的碳足迹数据采集模块，开展实施工作，包括：（1）进行相关配置；（2）打通BOM、工单、能源类数据，进行联调。所需开展实施工作明细后续下发指导手册。 | R2: 组织级口径，按项目公司分别计算后再汇总。 | S2: 源表未给出可计算的输入参数，须按 GB/T 24067 / ISO 14067 方法另建核算模型（涉及原材料消耗、各类排放因子等），建议单独出具碳足迹核算附表。
A3: IND-002 | B3: 开展产品碳足迹分析占比 | C3: 整体指标 | D3: 集采中心 | E3: 工厂 | F3: 指统计期内开展主要产品碳足迹分析的产品类别数量占主要产品类别总数的比值 | G3: CAR-010 ÷ CAR-011 × 100 | H3: CAR-010 CAR-011 | I3: 月度指标。 Rcf：开展产品碳足迹分析占比； Ncf:开展主要产品碳足迹分析的产品类别数量; N:主要产品类别总数 | J3: % | K3: 工厂 | L3: 国家级零碳工厂 | M3: 支撑绿色低碳管理体系、绿色低碳发展规划、温室气体盘查、能源管理体系、清洁生产、零碳工厂、绿色工厂等工作的开展 | N3: — | O3: 产品碳足迹系统提供开展产品碳足迹计算的产品种类明细。从ERP系统获取各单位全部产品种类明细。 | P3: 完成碳足迹数据采集模块的部署、配置，在电装统一部署的碳足迹在线核算及报告系统中完成能源-生产绑定工作。 | Q3: CAR-010、CAR-011 | R3: 组织级口径，按项目公司分别计算后再汇总。 | S3: 分子 · CAR-010 开展碳足迹分析的产品类别数量（个） ｜ 分母 · CAR-011 主要产品类别总数（个）
A4: IND-003 | B4: 综合能源消费量 | C4: 整体指标 | D4: 集控中心 | E4: 工厂 | F4: 指统计期内组织综合能源消费的总吨标准煤 | G4: Σ( EN-015 × EN-016 ) ÷ 1000 | H4: EN-014 EN-015 EN-016 | I4: 月度指标 E：综合能源消耗量，单位为tce n：消耗的能源种类数 Ei:实际消耗的第i种能源量 ki:第i种能源的折标准煤系数 | J4: tce | K4: 工厂 | L4: 国家级零碳工厂 | M4: — | N4: — | O4: 电（包括市电和绿电）、天然气、蒸汽、热力、柴油、煤油汽油等所有消耗能源种类的消耗量。其中核算综合能源消费量时，电力折标煤系数用当量值。 | P4: 1、各经营单位及项目公司完成电力、蒸汽、热力能源数据采集，并通过系统自动上送电装； 2、各经营单位及项目公司在集控中心开放的录入界面中按月录入购买绿电、绿证量，及按月录入难以自动采集的天然气、柴油、煤油、汽油（若能自动采集，则优先取自动采集数据，并通过系统自动上送电装）。 3、相关折标煤系数、碳排放因子由电装统一维护，各类指标电装统一计算。 | Q4: EN-014、EN-015、EN-016 | R4: 组织级口径，按项目公司分别计算后再汇总。 | S4: 维度 · EN-014 消耗的能源种类数（个） ｜ 因子 · EN-015 第 i 种能源消费量（各品种原单位） ｜ 系数 · EN-016 第 i 种能源折标准煤系数（kgce/单位或 tce/单位）
A5: IND-004 | B5: 总碳排放量 | C5: 整体指标 | D5: 集控中心 | E5: 工厂 | F5: 指统计期内企业组织产生的二氧化碳总排放量 | G5: ( CAR-002 + CAR-003 + CAR-004 + CAR-006 ) − ( CAR-005 + CAR-007 + CAR-008 ) | H5: CAR-002 CAR-003 CAR-004 CAR-005 CAR-006 CAR-007 CAR-008 | I5: 月度指标。由于电装产业在生产过程碳排放、回收利用中固碳非常少，且数据难统计，本次考虑能源碳排放。 C：二氧化碳排放量，单位为吨二氧化碳（tCO2）； C燃烧：化石燃料燃烧产生的二氧化碳排放量总和，单位为吨二氧化碳（tCO2） C过程：过程二氧化碳排放量总和，单位为吨二氧化碳（tCO2） C购入电：购入的电力所产生的二氧化碳排放，单位为吨二氧化碳（tCO2） C输出电：输出的电力所产生的二氧化碳排放，单位为吨二氧化碳（tCO2） C购入热：购入的热力所产生的二氧化碳排放，单位为吨二氧化碳（tCO2） C输出热：输出的热力所产生的二氧化碳排放，单位为吨二氧化碳（tCO2） C回收利用：化石燃料燃烧、工艺过程产生的二氧化碳经回收作为生产原料自用或作为产品外供并确保未再次排放所对应的二氧化碳排放量，单位为吨二氧化碳（tCO2） | J5: tCO2 | K5: 工厂 | L5: 国家级零碳工厂 | M5: — | N5: — | O5: 电（包括市电和绿电）、天然气、蒸汽、热力、柴油、煤油汽油等所有消耗能源种类的月度消耗量。电力消费量计算碳排放取省级电力平均二氧化碳排放因子。 | P5: — | Q5: CAR-002、CAR-003、CAR-004、CAR-005、CAR-006、CAR-007、CAR-008 | R5: 组织级口径，按项目公司分别计算后再汇总。 | S5: 加项 · CAR-002 化石燃料燃烧排放量（tCO2） ｜ 加项 · CAR-003 过程排放量（tCO2） ｜ 加项 · CAR-004 购入电力排放量（tCO2） ｜ 扣减项 · CAR-005 输出电力排放量（tCO2） ｜ 加项 · CAR-006 购入热力排放量（tCO2） ｜ 扣减项 · CAR-007 输出热力排放量（tCO2） ｜ 扣减项 · CAR-008 二氧化碳回收利用量（tCO2）
A6: IND-005 | B6: 单位能耗碳排放 | C6: 整体指标 | D6: 集控中心 | E6: 工厂 | F6: 指统计期内每消费一吨标准煤产生的二氧化碳排放量 | G6: CAR-001 ÷ EN-013 | H6: CAR-001 EN-013 | I6: 月度指标。 I:单位能耗碳排放 C：二氧化碳排放量，单位为tCO2 E：综合能源消耗量，单位为tce | J6: tCO2/tce | K6: 工厂 | L6: 国家级零碳工厂 | M6: — | N6: — | O6: 分子与分母的核算范围须保持一致。提供电（包括市电和绿电）、天然气、蒸汽、热力、柴油、煤油汽油等所有消耗能源种类的消耗量。其中电力消费量折算标煤按照等价值计算（电力标煤系数优先使用所在省的平均发电煤耗，无法获取的，使用0.2856kgce/kWh） | P6: — | Q6: CAR-001、EN-013 | R6: 组织级口径，按项目公司分别计算后再汇总。 | S6: 分子 · CAR-001 二氧化碳排放量（tCO2） ｜ 分母 · EN-013 综合能源消费量（tce）
A7: IND-006 | B7: 非化石能源消费占比 | C7: 整体指标 | D7: 集控中心 | E7: 工厂 | F7: 指统计期内非化石能源消费量与综合能源消费量的比值 | G7: EN-019 ÷ EN-018 × 100 | H7: EN-019 EN-018 | I7: 月度指标，交易绿电、绿证可纳入分子。 r：非化石能源消费占比 R:各类非化石能源消费量(不含作为原料使用的能源)，单位为tce E:综合能源消费量（不含作为原料使用的能源）,单位为tce | J7: % | K7: 工厂 | L7: 国家级零碳工厂 | M7: — | N7: — | O7: ①绿电等非化石能源的月度消耗量； ②电（包括市电和绿电）、天然气、蒸汽、热力、柴油、煤油汽油等所有消耗能源种类的消耗量。 | P7: — | Q7: EN-018、EN-019 | R7: 组织级口径，按项目公司分别计算后再汇总。 | S7: 分子 · EN-019 非化石能源消费量（不含原料用能）（tce） ｜ 分母 · EN-018 综合能源消费量（不含原料用能）（tce）
A8: IND-007 | B8: 非化石能源电力消费物理认定量占比 | C8: 整体指标 | D8: 集控中心 | E8: 工厂 | F8: 指统计期内具备物理可溯源条件的非化石能源电力消费量占同期总用电量的比值。 | G8: EN-005 ÷ EN-020 × 100 | H8: EN-005 EN-020 | I8: 月底指标，交易绿电、绿证不纳入分子。 Eui:非化石能源电力消费物理认定量占比； Ez:具备物理可溯源条件的非化石能源电力消费量，单位为kWh; Q:总用电量，单位为千kWh | J8: % | K8: 工厂 | L8: 国家级零碳工厂 | M8: — | N8: — | O8: 月度总用电量和具备物理可溯源条件的非化石能源电力消耗量（如自建消纳绿电及非自建绿电直连量） | P8: — | Q8: EN-005、EN-020 | R8: 组织级口径，按项目公司分别计算后再汇总。 | S8: 分子 · EN-005 非化石能源电力消费物理认定量（kWh） ｜ 分母 · EN-020 总用电量（kWh）
A9: IND-008 | B9: 单位工业增加值能耗 | C9: 整体指标 | D9: 集控中心 | E9: 工厂 | F9: 指统计期内综合能源消费量与工业增加值的比值 | G9: EN-013 ÷ VAL-001 | H9: EN-013 VAL-001 | I9: 月度指标，年度重新汇算。 Enva:单位工业增加值能耗，单位为tce/万元； E：综合能源消费量，单位tce Gnva:工业增加值，单位为万元 | J9: tce/万元 | K9: 工厂 | L9: 国家级零碳工厂 | M9: — | N9: — | O9: ①企业月度工业增加值； ②电（包括市电和绿电）、天然气、蒸汽、热力、柴油、煤油汽油等所有消耗能源种类的消耗量。 | P9: 各经营单位及项目公司在集控中心开放的界面中录入企业工业增加值，月度估算，年度汇算。 | Q9: EN-013、VAL-001 | R9: 组织级口径，按项目公司分别计算后再汇总。 | S9: 分子 · EN-013 综合能源消费量（tce） ｜ 分母 · VAL-001 工业增加值（万元）
A10: IND-009 | B10: 节能装备应用占比 | C10: 整体指标 | D10: 集控中心 | E10: 工厂 | F10: 指统计期内达到或优于能效强制性国家标准 2 级水平和《重点用能产品设备能效先进水平、节能水平和准入水平》节能水平的装备累计额定总功率占纳入统计范围装备累计额定总功率的比例 | G10: EQ-001 ÷ EQ-002 × 100 | H10: EQ-001 EQ-002 | I10: 月度指标。 S：节能装备应用占比； Res:达到或优于能效强制性国家标准 2 级水平和《重点用能产品设备能效先进水平、节能水平和准入水平》节能水平的装备累计额定总功率，单位为kW。 Ets:纳入统计范围装备累计额定总功率，单位为kW。纳入统计范围的装备需有适用的能效强制性国家标准，包括但不限于电动机、变压器、工业锅炉、风机、容积式空气压缩机、工业制冷设备、热泵等；无适用标准的装备不纳入统计。 | J10: % | K10: 工厂 | L10: 国家级零碳工厂 | M10: — | N10: — | O10: ①达到要求节能水平的装备累计额定总功率。 ②企业所有装备累计额定总功率。 | P10: 各经营单位及项目公司在集控中心开放的界面中录入节能装备明细、所有装备明细，增量更新。 | Q10: EQ-001、EQ-002 | R10: 组织级口径，按项目公司分别计算后再汇总。 | S10: 分子 · EQ-001 节能装备累计额定总功率（kW） ｜ 分母 · EQ-002 纳入统计范围装备累计额定总功率（kW）
A11: IND-010 | B11: 单位产值能耗 | C11: 整体指标 | D11: 集控中心 | E11: 工厂 | F11: 指统计期内综合能源消费量与产品产值的比值 | G11: EN-013 ÷ VAL-002 | H11: EN-013 VAL-002 | I11: 月度指标。 g:单位产值能耗，单位为tce/万元； E：综合能源消费量，单位tce G:产品产值，单位为万元 | J11: tce/万元 | K11: 工厂 | L11: 股份管理要求 | M11: — | N11: — | O11: ①各单位产值，其中线缆产值到产线，从大数据平台获取，日更新。变压器产值到项目公司，从经营日报管理系统获取，日更新。 ②电（包括市电和绿电）、天然气、蒸汽、热力、柴油、煤油汽油等所有消耗能源种类的消耗量。 | P11: 线缆产值在电装大数据平台，变压器产值在经营日报管理系统，以各经营单位及项目公司为对象进行计算。 | Q11: EN-013、VAL-002 | R11: 组织级口径，按项目公司分别计算后再汇总。 | S11: 分子 · EN-013 综合能源消费量（tce） ｜ 分母 · VAL-002 产品产值（万元）
A12: IND-011 | B12: 水资源消耗量 | C12: 整体指标 | D12: 集控中心 | E12: 工厂 | F12: 指企业在一定时期内，实际用于生产、生活等用途中未返回环境或未再次回用的水量 | G12: EN-026 | H12: — | I12: 月度指标。 | J12: t | K12: 工厂 | L12: ESG要求 | M12: — | N12: — | O12: ①各单位按照月度上报实际生活生产用水量； ②有中水或其他再生水使用的单位应该考虑循环使用量经计算处理后上报集团。 | P12: 无法通过系统上送数据的单位可以手动定期录入数据 | R12: 组织级口径，按项目公司分别计算后再汇总。 | S12: 参数 · EN-026 用水量（总量）（t）
A13: IND-012 | B13: 单位产品能耗（型号、ERP产品种类、电装产线大类） | C13: 产品管控 | D13: 集控中心 | E13: 工厂 | F13: 指统计期内综合能源总消费量与产品产量的比值 | G13: EN-P01 ÷ OUT-P01 | H13: EN-P01 OUT-P01 | I13: 月度指标。 e:单位产品能耗，单位为tce/产品单位； E：综合能源消费量，单位tce M:产品产量，单位为产品单位，如万kVA、万km*mm2等 | J13: tce/产品单位（例如万kVA、万km·mm²） | K13: 工厂 | L13: 电装管理要求 | M13: 电装内部管理，实现同类型产品横向（不同单位间）、纵向（不同时间段间）对比分析，实现与行业基准、行业标杆的对比 | N13: 沈变：沈变本部 衡变：本部、湖南电气、特能建 新变：超高压公司、天变公司、智能电气、京津冀智能科技 鲁缆：鲁缆本部、曙光公司 德缆：德缆 新缆：新疆电缆公司、新疆线缆厂 | O13: ①订单产量、订单型号； ②订单所消耗能源量：电（包括市电和绿电）、天然气、蒸汽、热力等。 ③型号-产品种类-产线的对应关系。 | P13: 1、各项目公司完成关键工序、车间用能的采集，并对接至本地数据采集模块； 2、各项目公司在碳足迹在线核算及报告系统，生产-能源绑定模块完成生产管理单元与能耗计量的绑定； 3、各项目公司按标准接口将生产工单传送至本地数据采集模块。 | Q13: EN-P01、OUT-P01 | R13: 须先建立「产品型号 × ERP 产品种类 × 电装产线大类」映射并完成能源分摊。 | S13: 分子 · EN-P01 产品综合能源消费量（型号口径）（tce） ｜ 分母 · OUT-P01 产品产量（型号 × 产品种类 × 产线大类）（万kVA / 万km·mm² / 台套 等）
A14: IND-013 | B14: 单位产品电耗 | C14: 产品管控 | D14: 集控中心 | E14: 公司级 | F14: 指统计期内电能源消费量（包括公辅设备）与产品产量的比值 | G14: EN-P02 ÷ OUT-P01 | H14: EN-P02 OUT-P01 | I14: 月度指标。 q电:单位产品电耗，单位为kWh/产品单位； Q电：电能源消费量，单位kWh M:产品产量，单位为产品单位，如万kVA、万km*mm2等 | J14: kWh/产品单位（例如万kVA、万km·mm²） | K14: 公司级 | L14: 电装管理要求 | M14: — | N14: — | O14: ①订单产量、订单型号； ②订单所消耗电（包括市电和绿电）。 ③型号-产品种类-产线的对应关系。 | P14: — | Q14: EN-P02、OUT-P01 | R14: 须先建立「产品型号 × ERP 产品种类 × 电装产线大类」映射并完成能源分摊。 | S14: 分子 · EN-P02 产品电力消费量（型号口径）（kWh） ｜ 分母 · OUT-P01 产品产量（型号 × 产品种类 × 产线大类）（万kVA / 万km·mm² / 台套 等）
A15: IND-014 | B15: 单位产品蒸汽消耗 | C15: 产品管控 | D15: 集控中心 | E15: 公司级 | F15: 指统计期内蒸汽能源消费量与产品产量的比值 | G15: EN-P03 ÷ OUT-P01 | H15: EN-P03 OUT-P01 | I15: 月度指标。 q蒸汽:单位产品蒸汽消耗，单位为GJ/产品单位； Q蒸汽：蒸汽能源消费量，单位GJ M:产品产量，单位为产品单位，如万kVA、万km*mm2等 | J15: GJ/产品单位（例如万kVA、万km·mm²） | K15: 公司级 | L15: 电装管理要求 | M15: — | N15: — | O15: ①订单产量、订单型号； ②订单所消耗蒸汽。 ③型号-产品种类-产线的对应关系。 | P15: — | Q15: EN-P03、OUT-P01 | R15: 须先建立「产品型号 × ERP 产品种类 × 电装产线大类」映射并完成能源分摊。 | S15: 分子 · EN-P03 产品蒸汽消费量（型号口径）（GJ） ｜ 分母 · OUT-P01 产品产量（型号 × 产品种类 × 产线大类）（万kVA / 万km·mm² / 台套 等）
A16: IND-015 | B16: 单位产品天然气消耗 | C16: 产品管控 | D16: 集控中心 | E16: 公司级 | F16: 指统计期内天然气能源消费量与产品产量的比值 | G16: EN-P04 ÷ OUT-P01 | H16: EN-P04 OUT-P01 | I16: 月度指标。 q天然气:单位产品天然气消耗，单位为m³/产品单位； Q天然气：天然气能源消费量，单位m³ M:产品产量，单位为产品单位，如万kVA、万km*mm2等 | J16: m³/产品单位（例如万kVA、万km·mm²） | K16: 公司级 | L16: 电装管理要求 | M16: — | N16: — | O16: ①订单产量、订单型号； ②订单所消耗天然气。 ③型号-产品种类-产线的对应关系。 | P16: — | Q16: EN-P04、OUT-P01 | R16: 须先建立「产品型号 × ERP 产品种类 × 电装产线大类」映射并完成能源分摊。 | S16: 分子 · EN-P04 产品天然气消费量（型号口径）（m³） ｜ 分母 · OUT-P01 产品产量（型号 × 产品种类 × 产线大类）（万kVA / 万km·mm² / 台套 等）
A17: IND-016 | B17: 单位产品水耗 | C17: 产品管控 | D17: 集控中心 | E17: 公司级 | F17: 指统计期内水能源消费量与产品产量的比值 | G17: EN-P05 ÷ OUT-P01 | H17: EN-P05 OUT-P01 | I17: 月度指标。 q水:单位产品水耗，单位为t/产品单位； Q水：水能源消费量，单位t M:产品产量，单位为产品单位，如万kVA、万km*mm2等 | J17: t/产品单位（例如万kVA、万km·mm²） | K17: 公司级 | L17: 电装管理要求 | M17: — | N17: — | O17: ①订单产量、订单型号； ②订单所消耗水。 ③型号-产品种类-产线的对应关系。 | P17: — | Q17: EN-P05、OUT-P01 | R17: 须先建立「产品型号 × ERP 产品种类 × 电装产线大类」映射并完成能源分摊。 | S17: 分子 · EN-P05 产品水消费量（型号口径）（t） ｜ 分母 · OUT-P01 产品产量（型号 × 产品种类 × 产线大类）（万kVA / 万km·mm² / 台套 等）
A18: IND-017 | B18: 吨铜电耗（线缆-导线-拉丝） | C18: 关键工序 | D18: 集控中心 | E18: 关键工序 | F18: 线缆导线产线，拉丝工序，拉1吨铜耗电量 | G18: EN-KE46 ÷ OUT-KM27 | H18: EN-KE46 OUT-KM27 | I18: 月度指标 q线缆-导线-拉丝Cu-电：导线产线中拉丝工序单位铜电耗，单位为kWh/t； Q线缆-导线-拉丝Cu-电：导线产线中拉丝工序电能源消费量，单位kWh M线缆-导线-拉丝Cu:导线产线中拉丝工序铜产量，单位为t | J18: kWh/t | K18: 关键工序 | L18: 电装管理要求 | M18: 电装内部管理，管控高能耗工序，用指标牵引项目公司主动节能，通过数据分析挖掘节能空间 | N18: 鲁缆本部、新疆线缆厂、德缆公司 | O18: ①导线产线拉丝工序耗电量 ②对应耗铜量 | P18: 采集拉丝（铜）设备的电耗，统计耗铜量，上送电装集控中心。 | Q18: EN-KE46、OUT-KM27 | R18: 分子取「本产线-本工序」能源计量点读数，分母取同产线同工序产量/产值，两者期间必须一致。 | S18: 分子 · EN-KE46 工序电力消费量（线缆-导线-拉丝·铜）（kWh） ｜ 分母 · OUT-KM27 工序产品产量（线缆-导线-拉丝·铜）（t）
A19: IND-018 | B19: 吨铝电耗（线缆-导线-拉丝） | C19: 关键工序 | D19: 集控中心 | E19: 关键工序 | F19: 线缆导线产线，拉丝工序，拉1吨铝耗电量 | G19: EN-KE47 ÷ OUT-KM28 | H19: EN-KE47 OUT-KM28 | I19: 月度指标 q线缆-导线-拉丝Al-电：导线产线中拉丝工序单位铝电耗，单位为kWh/t； Q线缆-导线-拉丝Al-电：导线产线中拉丝工序电能源消费量，单位kWh M线缆-导线-拉丝Al:导线产线中拉丝工序铝产量，单位为t | J19: kWh/t | K19: 关键工序 | L19: 电装管理要求 | M19: — | N19: — | O19: ①导线产线拉丝工序耗电量 ②对应耗铝量 | P19: 采集拉丝（铝）设备的电耗，统计耗铝量，上送电装集控中心。 | Q19: EN-KE47、OUT-KM28 | R19: 分子取「本产线-本工序」能源计量点读数，分母取同产线同工序产量/产值，两者期间必须一致。 | S19: 分子 · EN-KE47 工序电力消费量（线缆-导线-拉丝·铝）（kWh） ｜ 分母 · OUT-KM28 工序产品产量（线缆-导线-拉丝·铝）（t）
A20: IND-019 | B20: 吨铜电耗（线缆-布电线-拉丝） | C20: 关键工序 | D20: 集控中心 | E20: 关键工序 | F20: 线缆布电线产线，拉丝工序，拉1吨铜耗电量 | G20: EN-KE48 ÷ OUT-KM29 | H20: EN-KE48 OUT-KM29 | I20: 月度指标 q线缆-布电线-拉丝Cu-电：布电线产线中拉丝工序单位铜电耗，单位为kWh/t； Q线缆-布电线-拉丝Cu-电：布电线产线中拉丝工序电能源消费量，单位kWh M线缆-布电线-拉丝Cu:布电线产线中拉丝工序铜产量，单位为t | J20: kWh/t | K20: 关键工序 | L20: 电装管理要求 | M20: — | N20: 鲁缆本部、新疆线缆厂、新疆电缆、德缆公司 | O20: ①布电线产线拉丝工序耗电量 ②对应耗铜量 | P20: 采集拉丝（铜）设备的电耗，统计耗铜量，上送电装集控中心。 | Q20: EN-KE48、OUT-KM29 | R20: 分子取「本产线-本工序」能源计量点读数，分母取同产线同工序产量/产值，两者期间必须一致。 | S20: 分子 · EN-KE48 工序电力消费量（线缆-布电线-拉丝·铜）（kWh） ｜ 分母 · OUT-KM29 工序产品产量（线缆-布电线-拉丝·铜）（t）
A21: IND-020 | B21: 吨铝电耗（线缆-布电线-拉丝） | C21: 关键工序 | D21: 集控中心 | E21: 关键工序 | F21: 线缆布电线产线，拉丝工序，拉1吨铝耗电量 | G21: EN-KE49 ÷ OUT-KM30 | H21: EN-KE49 OUT-KM30 | I21: 月度指标 q线缆-布电线-拉丝Al-电：布电线产线中拉丝工序单位铝电耗，单位为kWh/t； Q线缆-布电线-拉丝Al-电：布电线产线中拉丝工序电能源消费量，单位kWh M线缆-布电线-拉丝Al:布电线产线中拉丝工序铝产量，单位为t | J21: kWh/t | K21: 关键工序 | L21: 电装管理要求 | M21: — | N21: — | O21: ①布电线产线拉丝工序耗电量 ②对应耗铝量 | P21: 采集拉丝（铝）设备的电耗，统计耗铝量，上送电装集控中心。 | Q21: EN-KE49、OUT-KM30 | R21: 分子取「本产线-本工序」能源计量点读数，分母取同产线同工序产量/产值，两者期间必须一致。 | S21: 分子 · EN-KE49 工序电力消费量（线缆-布电线-拉丝·铝）（kWh） ｜ 分母 · OUT-KM30 工序产品产量（线缆-布电线-拉丝·铝）（t）
A22: IND-021 | B22: 吨铜电耗（线缆-高压电缆-拉丝） | C22: 关键工序 | D22: 集控中心 | E22: 关键工序 | F22: 线缆高压电缆产线，拉丝工序，拉1吨铜耗电量 | G22: EN-KE57 ÷ OUT-KM38 | H22: EN-KE57 OUT-KM38 | I22: 月度指标 q线缆-高压电缆-拉丝Cu-电：高压电缆产线中拉丝工序单位铜电耗，单位为kWh/t； Q线缆-高压电缆-拉丝Cu-电：高压电缆产线中拉丝工序电能源消费量，单位kWh M线缆-高压电缆-拉丝Cu:高压电缆产线中拉丝工序铜产量，单位为t | J22: kWh/t | K22: 关键工序 | L22: 电装管理要求 | M22: — | N22: 鲁缆本部 | O22: ①高压电缆产线拉丝工序耗电量 ②对应耗铜量 | P22: 采集拉丝（铜）设备的电耗，统计耗铜量，上送电装集控中心。 | Q22: EN-KE57、OUT-KM38 | R22: 分子取「本产线-本工序」能源计量点读数，分母取同产线同工序产量/产值，两者期间必须一致。 | S22: 分子 · EN-KE57 工序电力消费量（线缆-高压电缆-拉丝·铜）（kWh） ｜ 分母 · OUT-KM38 工序产品产量（线缆-高压电缆-拉丝·铜）（t）
A23: IND-022 | B23: 吨铝电耗（线缆-高压电缆-拉丝） | C23: 关键工序 | D23: 集控中心 | E23: 关键工序 | F23: 线缆高压电缆产线，拉丝工序，拉1吨铝耗电量 | G23: EN-KE58 ÷ OUT-KM39 | H23: EN-KE58 OUT-KM39 | I23: 月度指标 q线缆-高压电缆-拉丝Al-电：高压电缆产线中拉丝工序单位铝电耗，单位为kWh/t； Q线缆-高压电缆-拉丝Al-电：高压电缆产线中拉丝工序电能源消费量，单位kWh M线缆-高压电缆-拉丝Al:高压电缆产线中拉丝工序铝产量，单位为t | J23: kWh/t | K23: 关键工序 | L23: 电装管理要求 | M23: — | N23: — | O23: ①高压电缆产线拉丝工序耗电量 ②对应耗铝量 | P23: 采集拉丝（铝）设备的电耗，统计耗铝量，上送电装集控中心。 | Q23: EN-KE58、OUT-KM39 | R23: 分子取「本产线-本工序」能源计量点读数，分母取同产线同工序产量/产值，两者期间必须一致。 | S23: 分子 · EN-KE58 工序电力消费量（线缆-高压电缆-拉丝·铝）（kWh） ｜ 分母 · OUT-KM39 工序产品产量（线缆-高压电缆-拉丝·铝）（t）
A24: IND-023 | B24: 高压交联（干法）（线缆-高压电缆-交联） | C24: 关键工序 | D24: 集控中心 | E24: 关键工序 | F24: 线缆高压电缆产线，交联工序，单位产量耗电量。 | G24: EN-KE56 ÷ OUT-KM37 | H24: EN-KE56 OUT-KM37 | I24: 月度指标 q线缆-高压电缆-交联-电：高压电缆产线中交联工序单位产品电耗，单位为kWh/km*mm2； Q线缆-高压电缆-交联-电：高压电缆产线中交联工序电能源消费量，单位kWh M线缆-高压电缆-交联:高压电缆产线中交联工序产品产量，单位为km*mm2 | J24: kWh/km·mm² | K24: 关键工序 | L24: 电装管理要求 | M24: — | N24: — | O24: ①高压电缆产线交联工序耗电量 ②对应线缆产量。ERP里有，入库的公里数*截面，km*mm2 | P24: 采集高压产线交联设备的电耗，统计对应线缆产量，上送电装集控中心。 | Q24: EN-KE56、OUT-KM37 | R24: 分子取「本产线-本工序」能源计量点读数，分母取同产线同工序产量/产值，两者期间必须一致。 | S24: 分子 · EN-KE56 工序电力消费量（线缆-高压电缆-交联）（kWh） ｜ 分母 · OUT-KM37 工序产品产量（线缆-高压电缆-交联）（km·mm²）
... A95: IND-094 | B95: 单位产量电耗（硅钢铁心-大型叠装） | C95: 关键工序 | D95: 集控中心 | E95: 关键工序 | F95: 生产每t硅钢铁心，大型叠装工序耗电量 | G95: EN-KE39 ÷ OUT-KM20 | H95: EN-KE39 OUT-KM20 | I95: 月度指标 q硅钢-大型叠装-电：硅钢铁心大型叠装工序中单位产品电耗，单位为kWh/t； Q硅钢-大型叠装-电：硅钢铁心大型叠装工序中电能源消费量，单位kWh M硅钢-大型叠装:硅钢铁心大型叠装工序产品产量，单位为t | J95: kWh/t | K95: 关键工序 | L95: 电装管理要求 | M95: — | N95: — | O95: ①硅钢铁心-大型叠装工序耗电量 ②对应硅钢铁心产品产量。 | P95: 采集大型叠装设备的电耗。统计对应硅钢铁心产量，上送电装集控中心。 | Q95: EN-KE39、OUT-KM20 | R95: 分子取「本产线-本工序」能源计量点读数，分母取同产线同工序产量/产值，两者期间必须一致。 | S95: 分子 · EN-KE39 工序电力消费量（硅钢铁心-大型叠装）（kWh） ｜ 分母 · OUT-KM20 工序产品产量（硅钢铁心-大型叠装）（t）

Sheet 04-公式变量映射
A1: 指标编码 | B1: 指标名称 | C1: 颗粒度层级 | D1: 变量序号 | E1: 变量符号（原表） | F1: 变量角色 | G1: 对应参数编码 | H1: 对应数据项名称 | I1: 变量单位 | J1: 所属产线 | K1: 所属工序 | L1: 变量含义（原表）
A2: IND-002 | B2: 开展产品碳足迹分析占比 | C2: 工厂级 | D2: 1 | E2: Rcf | F2: 单位指标值（即本指标被计算量） | G2: IND-002 | H2: — | I2: — | J2: — | K2: — | L2: 开展产品碳足迹分析占比
A3: IND-002 | B3: 开展产品碳足迹分析占比 | C3: 工厂级 | D3: 2 | E3: Ncf | F3: 分子 | G3: CAR-010 | H3: — | I3: — | J3: — | K3: — | L3: 开展主要产品碳足迹分析的产品类别数量
A4: IND-002 | B4: 开展产品碳足迹分析占比 | C4: 工厂级 | D4: 3 | E4: N | F4: 分母 | G4: CAR-011 | H4: — | I4: — | J4: — | K4: — | L4: 主要产品类别总数
A5: IND-003 | B5: 综合能源消费量 | C5: 工厂级 | D5: 1 | E5: E | F5: 单位指标值（即本指标被计算量） | G5: IND-003 | H5: — | I5: tce | J5: — | K5: — | L5: 综合能源消耗量，单位为tce
A6: IND-003 | B6: 综合能源消费量 | C6: 工厂级 | D6: 2 | E6: n | F6: 维度（能源品种计数） | G6: EN-014 | H6: — | I6: — | J6: — | K6: — | L6: 消耗的能源种类数
A7: IND-003 | B7: 综合能源消费量 | C7: 工厂级 | D7: 3 | E7: Ei | F7: 因子（第 i 种能源消费量） | G7: EN-015 | H7: — | I7: — | J7: — | K7: — | L7: 实际消耗的第i种能源量
A8: IND-003 | B8: 综合能源消费量 | C8: 工厂级 | D8: 4 | E8: ki | F8: 系数（第 i 种能源折标准煤系数） | G8: EN-016 | H8: — | I8: — | J8: — | K8: — | L8: 第i种能源的折标准煤系数
A9: IND-004 | B9: 总碳排放量 | C9: 工厂级 | D9: 1 | E9: C | F9: 单位指标值（即本指标被计算量） | G9: IND-004 | H9: — | I9: 吨二氧化碳（tCO2 | J9: — | K9: — | L9: 二氧化碳排放量，单位为吨二氧化碳（tCO2）
A10: IND-004 | B10: 总碳排放量 | C10: 工厂级 | D10: 2 | E10: C燃烧 | F10: 加项·碳排放分量 | G10: CAR-002 | H10: — | I10: 吨二氧化碳（tCO2 | J10: — | K10: — | L10: 化石燃料燃烧产生的二氧化碳排放量总和，单位为吨二氧化碳（tCO2）
A11: IND-004 | B11: 总碳排放量 | C11: 工厂级 | D11: 3 | E11: C过程 | F11: 加项·碳排放分量 | G11: CAR-003 | H11: — | I11: 吨二氧化碳（tCO2 | J11: — | K11: — | L11: 过程二氧化碳排放量总和，单位为吨二氧化碳（tCO2）
A12: IND-004 | B12: 总碳排放量 | C12: 工厂级 | D12: 4 | E12: C购入电 | F12: 加项·碳排放分量 | G12: CAR-004 | H12: — | I12: 吨二氧化碳（tCO2 | J12: — | K12: — | L12: 购入的电力所产生的二氧化碳排放，单位为吨二氧化碳（tCO2）
A13: IND-004 | B13: 总碳排放量 | C13: 工厂级 | D13: 5 | E13: C输出电 | F13: 扣减项·碳排放分量 | G13: CAR-005 | H13: — | I13: 吨二氧化碳（tCO2 | J13: — | K13: — | L13: 输出的电力所产生的二氧化碳排放，单位为吨二氧化碳（tCO2）
... A283: IND-094 | B283: 单位产量电耗（硅钢铁心-大型叠装） | C283: 工序级 | D283: 3 | E283: M硅钢-大型叠装 | F283: 分母·产量 | G283: OUT-KM20 | H283: — | I283: t | J283: 硅钢铁心 | K283: 大型叠装 | L283: 硅钢铁心大型叠装工序产品产量，单位为t

Sheet 05-工序数据项矩阵
A1: 05 · 工序数据项矩阵（最小颗粒度展开对照）
A2: 共 51 个「产线 × 工序」组合。
A3: 序号 | B3: 产线 | C3: 工序 | D3: 电力消费量 编码 | E3: 蒸汽消费量 编码 | F3: 综合能源消费量 编码 | G3: 产品产量 编码 | H3: 产品产值 编码 | I3: 电力消费量 单位 | J3: 蒸汽消费量 单位 | K3: 综合能源消费量 单位 | L3: 产品产量 单位 | M3: 产品产值 单位 | N3: 关联指标
A4: 1 | B4: GIL | C4: 测试 | D4: EN-KE01 | E4: — | F4: — | G4: — | H4: VAL-KG01 | I4: kWh | J4: — | K4: — | L4: — | M4: 万元 | N4: IND-085
A5: 2 | B5: GIL | C5: 绝缘子生产 | D5: EN-KE02 | E5: — | F5: — | G5: — | H5: VAL-KG02 | I5: kWh | J5: — | K5: — | L5: — | M5: 万元 | N5: IND-086
A6: 3 | B6: GIL | C6: 螺旋焊管生产 | D6: EN-KE03 | E6: — | F6: — | G6: — | H6: VAL-KG03 | I6: kWh | J6: — | K6: — | L6: — | M6: 万元 | N6: IND-084
A7: 4 | B7: GIS | C7: 工频耐压试验 | D7: EN-KE04 | E7: — | F7: — | G7: — | H7: VAL-KG04 | I7: kWh | J7: — | K7: — | L7: — | M7: 万元 | N7: IND-089
A8: 5 | B8: GIS | C8: 抽真空 | D8: EN-KE05 | E8: — | F8: — | G8: — | H8: VAL-KG05 | I8: kWh | J8: — | K8: — | L8: — | M8: 万元 | N8: IND-087
A9: 6 | B9: GIS | C9: 空调恒温除湿 | D9: EN-KE06 | E9: — | F9: — | G9: — | H9: VAL-KG06 | I9: kWh | J9: — | K9: — | L9: — | M9: 万元 | N9: IND-090
A10: 7 | B10: GIS | C10: 绝缘件干燥 | D10: EN-KE07 | E10: — | F10: — | G10: — | H10: VAL-KG07 | I10: kWh | J10: — | K10: — | L10: — | M10: 万元 | N10: IND-088
A11: 8 | B11: 中低压开关柜 | C11: 钣金加工 | D11: EN-KE08 | E11: — | F11: — | G11: — | H11: VAL-KG08 | I11: kWh | J11: — | K11: — | L11: — | M11: 万元 | N11: IND-066
A12: 9 | B12: 中低压开关柜 | C12: 钣金喷涂 | D12: EN-KE09 | E12: — | F12: — | G12: — | H12: VAL-KG09 | I12: kWh | J12: — | K12: — | L12: — | M12: 万元 | N12: IND-067
A13: 10 | B13: 二次 | C13: SMT贴片 | D13: EN-KE10 | E13: — | F13: — | G13: — | H13: VAL-KG10 | I13: kWh | J13: — | K13: — | L13: — | M13: 万元 | N13: IND-075
A14: 11 | B14: 二次 | C14: 波峰焊 | D14: EN-KE11 | E14: — | F14: — | G14: — | H14: VAL-KG11 | I14: kWh | J14: — | K14: — | L14: — | M14: 万元 | N14: IND-077
A15: 12 | B15: 二次 | C15: 高温老化 | D15: EN-KE12 | E15: — | F15: — | G15: — | H15: VAL-KG12 | I15: kWh | J15: — | K15: — | L15: — | M15: 万元 | N15: IND-076
... A54: 51 | B54: 非晶合金铁心 | C54: 退火 | D54: EN-KE59 | E54: — | F54: — | G54: OUT-KM40 | H54: — | I54: kWh | J54: — | K54: — | L54: t | M54: — | N54: IND-091

Sheet 06-数据源清单
A1: 06 · 数据源清单
A2: 共 12 个数据源。工序级数据项的来源系统与责任方见「02-基础参数表」对应行。
A3: 序号 | B3: 数据源编码 | C3: 数据源系统 / 部门 | D3: 提供方 | E3: 提供数据内容 | F3: 对接方式 | G3: 数据频率 | H3: 责任方 | I3: 备注
A4: 1 | B4: SRC-01 | C4: 集控中心（能碳管控平台） | D4: 电装（集团） | E4: 各能源品种计量数据、能耗指标计算结果、手工录入数据（绿电 / 绿证、工业增加值、用水量、装备台账） | F4: 平台内部 | G4: 实时 / 月度 | H4: 电装信息化 | I4: 指标计算与展示主平台，集控类指标的权威数据源
A5: 2 | B5: SRC-02 | C5: 碳足迹在线核算及报告系统 | D5: 电装（集团） | E5: 产品碳足迹值、开展碳足迹分析的产品种类明细、生产-能源绑定关系 | F5: 系统对接 | G5: 实时 / 月度 | H5: 电装 | I5: 支撑 IND-001、IND-002，并回流绑定关系至集控中心
A6: 3 | B6: SRC-03 | C6: 本地数据采集模块 | D6: 各项目公司 | E6: 关键工序、车间用能数据（电 / 蒸汽 / 天然气 / 热力） | F6: 边缘采集 → 集控中心 | G6: 实时 | H6: 各项目公司 | I6: 工序级指标的唯一数据入口，需完成部署与联调
A7: 4 | B7: SRC-04 | C7: ERP 系统 | D7: 各项目公司 | E7: 产品型号、产品种类、订单产量、入库公里数与截面、物料数据、生产工单、主要产品类别总数 | F7: 标准接口 | G7: 日 / 月度 | H7: 各项目公司 / 电装信息化 | I7: 产量与产品主数据的来源
A8: 5 | B8: SRC-05 | C8: MES 系统 | D8: 部分项目公司 | E8: 生产工单、工序产量、工序产值（如 GIS 抽真空 / 干燥 / 试验 / 除湿工序产值） | F8: 标准接口 | G8: 日 / 月度 | H8: 各项目公司 | I8: —
A9: 6 | B9: SRC-06 | C9: 电装大数据平台 | D9: 电装（集团） | E9: 线缆产值（颗粒度到产线） | F9: 系统对接 | G9: 日更新 | H9: 电装 | I9: IND-010 单位产值能耗的分母来源之一
A10: 7 | B10: SRC-07 | C10: 经营日报管理系统 | D10: 各项目公司 | E10: 变压器产值（颗粒度到项目公司） | F10: 系统对接 | G10: 日更新 | H10: 各项目公司 | I10: IND-010 单位产值能耗的分母来源之一
A11: 8 | B11: SRC-08 | C11: 集团主数据管理系统 | D11: 集团 | E11: 组织主数据（经营单位 / 项目公司编码与名称、产业分类） | F11: 系统对接 | G11: 变更时同步 | H11: 集团 / 电装信息化 | I11: 组织维度的统一口径
A12: 9 | B12: SRC-09 | C12: 集控中心录入界面 | D12: 各项目公司 | E12: 绿电 / 绿证量、天然气 / 柴油 / 汽油 / 煤油（无法自动采集时）、工业增加值、用水量、节能装备台账 | F12: 手工录入 | G12: 月度 / 增量更新 | H12: 各项目公司 | I12: 自动采集不覆盖项的手工兜底通道
A13: 10 | B13: SRC-10 | C13: 省级电网 / 生态环境主管部门公布口径 | D13: 外部 | E13: 省级电力平均二氧化碳排放因子、所在省平均发电煤耗 | F13: 外部引用 | G13: 年度 | H13: 电装 | I13: 计算系数（FAC-002、FAC-009）的维护依据
A14: 11 | B14: SRC-11 | C14: 项目公司能碳系统 / 能源管理系统（EMS） | D14: 各项目公司 | E14: 关口表电量（累计发电 / 市电 / 消纳 / 上网 / 负荷）、实时功率、分时电量、储能运行数据、重点设备用电与蒸汽数据、热泵与空调系统运行数据 | F14: 系统接入 → 集控中心 | G14: 实时（15 分钟）/ 日 | H14: 各项目公司 | I14: 零碳园区集控中心域的主要数据入口，对应数据需求清单「项目公司能碳系统接入」
A15: 12 | B15: SRC-12 | C15: 双中心系统界面（手工录入 / 批量导入） | D15: 各项目公司 | E15: 园区配置信息（光伏装机、变压器容量、储能装机、照片）、零碳项目信息、零碳关键事件、绿电与绿证量、能源费用、工业增加值、设备台账、重点设备额定负荷、热泵与空调服务面积 | F15: 界面录入 / 批量导入 | G15: 静态（变更时更新）/ 月度 | H15: 各项目公司 | I15: 对应数据需求清单「双中心系统界面手动录入」，自动采集不覆盖的台账与交易类数据的兜底通道

Sheet 07-枚举字典
A1: 07 · 枚举字典
A2: 共 185 条取值。产线、工序、物料等维度取值以此为准。
A3: 序号 | B3: 字典编码 | C3: 字典名称 | D3: 取值 | E3: 取值说明 | F3: 关联参数编码 | G3: 备注
A4: 1 | B4: ORG-01 | C4: 经营单位 | D4: 沈变 | E4: 集团下 6 家经营单位（产业板块级） | F4: ORG-001 经营单位编码 / ORG-002 经营单位名称 | G4: 各经营单位下辖多个项目公司
A5: 2 | B5: ORG-01 | C5: 经营单位 | D5: 衡变 | E5: 集团下 6 家经营单位（产业板块级） | F5: ORG-001 经营单位编码 / ORG-002 经营单位名称 | G5: 各经营单位下辖多个项目公司
A6: 3 | B6: ORG-01 | C6: 经营单位 | D6: 新变 | E6: 集团下 6 家经营单位（产业板块级） | F6: ORG-001 经营单位编码 / ORG-002 经营单位名称 | G6: 各经营单位下辖多个项目公司
A7: 4 | B7: ORG-01 | C7: 经营单位 | D7: 鲁缆 | E7: 集团下 6 家经营单位（产业板块级） | F7: ORG-001 经营单位编码 / ORG-002 经营单位名称 | G7: 各经营单位下辖多个项目公司
A8: 5 | B8: ORG-01 | C8: 经营单位 | D8: 德缆 | E8: 集团下 6 家经营单位（产业板块级） | F8: ORG-001 经营单位编码 / ORG-002 经营单位名称 | G8: 各经营单位下辖多个项目公司
A9: 6 | B9: ORG-01 | C9: 经营单位 | D9: 新缆 | E9: 集团下 6 家经营单位（产业板块级） | F9: ORG-001 经营单位编码 / ORG-002 经营单位名称 | G9: 各经营单位下辖多个项目公司
A10: 7 | B10: ORG-02 | C10: 项目公司 | D10: 沈变：沈变本部、和新套管、康嘉互感器 | E10: 各经营单位下属项目公司清单（指标覆盖范围与上报主体） | F10: ORG-003 项目公司编码 / ORG-004 项目公司名称 | G10: 原表覆盖范围列口径，共 6 家经营单位、22 个项目公司
A11: 8 | B11: ORG-02 | C11: 项目公司 | D11: 衡变：衡变本部、南京电研、云集电气、湖南电气、云集高压开关、新疆自控、特能建、合容电气、赛杰爱迪 | E11: 各经营单位下属项目公司清单（指标覆盖范围与上报主体） | F11: ORG-003 项目公司编码 / ORG-004 项目公司名称 | G11: 原表覆盖范围列口径，共 6 家经营单位、22 个项目公司
A12: 9 | B12: ORG-02 | C12: 项目公司 | D12: 新变：新变超高压公司、新变天变公司、新变智能电气、新变京津冀智能科技、珠峰硅钢 | E12: 各经营单位下属项目公司清单（指标覆盖范围与上报主体） | F12: ORG-003 项目公司编码 / ORG-004 项目公司名称 | G12: 原表覆盖范围列口径，共 6 家经营单位、22 个项目公司
A13: 10 | B13: ORG-02 | C13: 项目公司 | D13: 鲁缆：鲁缆本部、曙光公司 | E13: 各经营单位下属项目公司清单（指标覆盖范围与上报主体） | F13: ORG-003 项目公司编码 / ORG-004 项目公司名称 | G13: 原表覆盖范围列口径，共 6 家经营单位、22 个项目公司
A14: 11 | B14: ORG-02 | C14: 项目公司 | D14: 德缆：德缆公司 | E14: 各经营单位下属项目公司清单（指标覆盖范围与上报主体） | F14: ORG-003 项目公司编码 / ORG-004 项目公司名称 | G14: 原表覆盖范围列口径，共 6 家经营单位、22 个项目公司
A15: 12 | B15: ORG-02 | C15: 项目公司 | D15: 新缆：新疆电缆公司、新疆线缆厂 | E15: 各经营单位下属项目公司清单（指标覆盖范围与上报主体） | F15: ORG-003 项目公司编码 / ORG-004 项目公司名称 | G15: 原表覆盖范围列口径，共 6 家经营单位、22 个项目公司
... A188: 185 | B188: ZC-06 | C188: 能源费用科目 | D188: 氮气费用 | E188: 工厂能源成本台账的费用科目，与实物量一一对应 | F188: CO-001~CO-006 能源费用 | G188: CO-001↔EN-026、CO-002↔EN-006、CO-003↔EN-031、CO-004↔EN-032、CO-005↔EN-002、CO-006↔EN-030

Sheet 08-数据接入对照
A1: 08 · 数据需求清单 → 基础参数编码 逐项对照
A2: 覆盖《“双中心”数据需求清单9.16》全部 78 项（集控 76 + 集采 2），并纳入 8.27 V1.0 版独有而 9.16 版删除的 15 项（保留理由见「处理说明」列）。「清单版本」列标注来源版本；「对应参数编码」列为该清单项的落库编码，含「+」表示按最小颗粒度拆为多个编码（拆分依据见「处理说明」列）。
A3: 序号 | B3: 数据域 / 中心 | C3: 数据类型 | D3: 数据项名称（清单原文） | E3: 数据单位（清单） | F3: 数据对象 | G3: 数据来源（清单原文） | H3: 采集频率（清单） | I3: 业务用途（清单原文） | J3: 对应参数编码 | K3: 清单版本 | L3: 处理说明 / 差异与口径提示
A4: 1 | B4: 零碳园区集控中心 | C4: 静态数据 | D4: 光伏装机量 | E4: MW | F4: 园区/工厂 | G4: 双中心系统界面手动录入 | H4: 多家工厂在一个园区的，提供园区整体数据 | I4: 大屏展示 | J4: ZP-001 | K4: 9.16 | L4: 直接对应。0.16/8.27 版来源为「系统接入」，9.16 版改为「界面手动录入」，开发以 9.16 为准。
A5: 2 | B5: 零碳园区集控中心 | C5: 静态数据 | D5: 变压器容量 | E5: MVA | F5: 园区/工厂 | G5: 双中心系统界面手动录入 | H5: 多家工厂在一个园区的，提供园区整体数据 | I5: — | J5: ZP-002 | K5: 9.16 | L5: 直接对应。园区 / 工厂供电能力参数。
A6: 3 | B6: 零碳园区集控中心 | C6: 静态数据 | D6: 储能装机容量 | E6: MW/MWh | F6: 园区/工厂 | G6: 双中心系统界面手动录入 | H6: 多家工厂在一个园区的，提供园区整体数据 | I6: — | J6: ZP-003 + ZP-004 | K6: 9.16 | L6: 【拆分】清单原文为复合单位「MW/MWh」，按最小颗粒度拆为「储能装机功率（MW）」与「储能装机容量（MWh）」两条。
A7: 4 | B7: 零碳园区集控中心 | C7: 静态数据 | D7: 园区照片 | E7: / | F7: 园区/工厂 | G7: 双中心系统界面手动录入 | H7: 多家工厂在一个园区的，提供园区整体数据 | I7: — | J7: ZP-005 | K7: 9.16 | L7: 非数值型展示资源，作参数管理但不参与计算。
A8: 5 | B8: 零碳园区集控中心 | C8: 动态数据 | D8: 零碳项目基本信息、照片 | E8: / | F8: 园区/工厂 | G8: 双中心系统界面手动录入 | H8: 增量更新 | I8: 大屏展示、零碳项目评估 | J8: ZP-006 | K8: 9.16 | L8: 直接对应。建议进一步拆为项目名称 / 建设内容 / 投运时间 / 容量 / 投资额等结构化子字段。
A9: 6 | B9: 零碳园区集控中心 | C9: 动态数据 | D9: 累计发电量（表底值） | E9: MWh | F9: 园区及工厂 | G9: 项目公司能碳系统接入 | H9: 15分钟 | I9: 大屏展示、集中监管、能效分析 | J9: NE-001 | K9: 9.16 | L9: 直接对应。口径为累计表底值，须同时留存储值快照时间。
A10: 7 | B10: 零碳园区集控中心 | C10: 动态数据 | D10: 累计市电电量（表底值） | E10: MWh | F10: 园区及工厂 | G10: 项目公司能碳系统接入 | H10: 15分钟 | I10: 大屏展示、集中监管、能效分析 | J10: LD-001（同 EN-002） | K10: 9.16 | L10: 单位为 MWh；「EN-002 市电消费量」为其 kWh 统一存储口径，二者 1 MWh = 1000 kWh。
A11: 8 | B11: 零碳园区集控中心 | C11: 动态数据 | D11: 累计消纳电量 | E11: MWh | F11: 园区及工厂 | G11: 项目公司能碳系统接入 | H11: 15分钟 | I11: 大屏展示、集中监管、能效分析 | J11: NE-002 | K11: 9.16 | L11: 直接对应。绿电物理认定的依据之一。
A12: 9 | B12: 零碳园区集控中心 | C12: 动态数据 | D12: 累计上网电量（表底值） | E12: MWh | F12: 园区及工厂 | G12: 项目公司能碳系统接入 | H12: 15分钟 | I12: 大屏展示、集中监管、能效分析 | J12: NE-003 | K12: 9.16 | L12: 直接对应。与 RV-001 绿电上网收益互为量价关系。
A13: 10 | B13: 零碳园区集控中心 | C13: 动态数据 | D13: 绿电上网收益 | E13: 万元 | F13: 园区 | G13: 项目公司能碳系统接入 | H13: 15分钟 | I13: 集中监管、零碳项目评估 | J13: RV-001 | K13: 9.16 | L13: 直接对应。
A14: 11 | B14: 零碳园区集控中心 | C14: 动态数据 | D14: 绿电消纳收益 | E14: 万元 | F14: 园区 | G14: 项目公司能碳系统接入 | H14: 15分钟 | I14: 集中监管、零碳项目评估 | J14: RV-002 | K14: 9.16 | L14: 直接对应。
A15: 12 | B15: 零碳园区集控中心 | C15: 动态数据 | D15: 累计负荷用电量（表底值） | E15: MWh | F15: 园区及工厂 | G15: 项目公司能碳系统接入 | H15: 15分钟 | I15: 大屏展示、集中监管、能效分析 | J15: LD-002 | K15: 9.16 | L15: 直接对应。用于园区总用电平衡校验。
... A96: 93 | B96: 零碳园区集控中心（8.27 保留项） | C96: 动态数据 | D96: 关键工序能耗指标 | E96: — | F96: 园区/工厂 | G96: 项目公司能碳系统接入 | H96: — | I96: 集中监管、能效分析 | J96: MT-001（→ EN-KE / EN-KS / EN-KT + OUT-KM + VAL-KG） | K96: 8.27 | L96: 9.16 版改称「生产单元能耗计量数据」。原文要求上送「指标值及对应的分子、分母、统计周期」，即 MT-001 原始时序 → 月度汇总 → 指标值三层结构。
A98: A | C98: 两版清单差异 | E98: 9.16 版共 78 项（集控 76 + 集采 2），8.27 V1.0 版共 66 项。9.16 版新增：重点设备额定负荷 / 蒸汽瞬时流量 / 蒸汽消耗量（3 项）、热泵与空调系统完整运行参数（20 项）、氮气费用、生产单元-能耗计量绑定关系、生产单元能耗计量数据；9.16 版删除：零碳关键事件、储能日充放分时电量（10 项）、产量（线缆 / 非线缆）2 项、订单能耗、关键工序能耗指标。删除项中凡对指标计算或能效分析有价值的，本版均予保留并在「八」列标注理由。
A99: B | C99: 单位口径冲突（须开发前确认） | E99: ① 油品：清单按「L」，V1.0 参数表柴油 / 汽油 / 煤油按「t」→ 新增 EN-032（L）与 FAC-015~017 密度系数换算；② 绿证：V1.0 作「张 / MWh」复合单位，统一为「个（张）」计数（GV-002）；③ 电量：清单用 MWh，V1.0 用 kWh，统一以 kWh 存储（EN-002 / EN-003），MWh 仅作展示（LD-001 / GV-001）；④ 储能收益单位「元」与绿电收益「万元」不一致；⑤ 储能装机容量「MW/MWh」复合单位已拆为 ZP-003 + ZP-004。
A100: C | C100: 新增数据域（V2.1） | E100: 本次共新增 92 项参数：既有域补充 7 项（EN-030~032 液氮 / 外购蒸汽 / 油品合计、FAC-014~017 液氮折标煤与油品密度系数），零碳园区与集控中心数据域 85 项（ZP- 园区基础配置 7、NE- 新能源与储能 20、LD- 园区负荷 10、GV- 绿色电力 2、RV- 收益 3、EQ- 重点设备运行 10、HV- 暖通系统 20、CO- 能源费用 6、OD- 订单 5、MT- 计量 2）。
A101: D | C101: 保留但提示偏差的清单项 | E101: 9.16 清单第 48 / 58 项（热泵供热面积、空调供冷面积）数据来源标「界面手动录入」但备注写「15 分钟」，本版按静态台账处理（变更时更新）；第 36 项重点设备额定负荷亦为静态数据。
A102: E | C102: 非参数类清单内容 | E102: 「服务器资源」段（存储 / 应用 / 数据接入 / 算力 / 智能体服务器配置）属硬件与部署需求，不进入基础参数表，由项目实施文档单独承载。

Sheet 09-指标参数构成明细
A1: 09 · 指标参数构成明细（指标 → 参数 → 分项 全展开）
A2: 共 214 行，覆盖全部 94 个指标。第 ① 层为该指标的公式输入项（分子 / 分母 / 加项 / 扣减项等）；第 ②③ 层为复合参数（如「综合能源消费量」）继续拆出的最小颗粒度分项。开发实现时，原子参数直接取数，复合参数按其分项折算或上送。
A3: 序号 | B3: 指标编码 | C3: 指标名称 | D3: 指标体系 | E3: 指标单位 | F3: 规范计算公式（按参数编码） | G3: 层级 | H3: 参数角色 | I3: 参数编码 | J3: 参数名称 | K3: 参数性质 | L3: 单位 | M3: 数据类别 | N3: 所属产线 | O3: 所属工序 | P3: 数据来源 | Q3: 获取方式 | R3: 责任单位 | S3: 构成说明 / 备注
A4: 1 | B4: IND-001 | C4: 产品碳足迹 | D4: 整体指标 | E4: tCo2/台套，tCo2/km等 | F4: 按 GB/T 24067、ISO 14067 方法核算（摇篮到大门） | G4: ① 输入项 | H4: — | I4: — | J4: — | K4: 无输入参数 | L4: — | M4: — | N4: — | O4: — | P4: — | Q4: — | R4: — | S4: 源表未给出可计算的输入参数，须按 GB/T 24067 / ISO 14067 方法另建核算模型（涉及原材料消耗、各类排放因子等），建议单独出具碳足迹核算附表。
A5: 2 | B5: IND-002 | C5: 开展产品碳足迹分析占比 | D5: 整体指标 | E5: % | F5: CAR-010 ÷ CAR-011 × 100 | G5: ① 输入项 | H5: 分子 | I5: CAR-010 | J5: 开展碳足迹分析的产品类别数量 | K5: 原子参数 | L5: 个 | M5: 碳排放数据 | N5: — | O5: — | P5: 碳足迹在线核算及报告系统 | Q5: 系统对接 | R5: 各项目公司 | S5: 指标直接输入项。统计期内开展主要产品碳足迹分析的产品类别数量
A6: 3 | B6: IND-002 | C6: 开展产品碳足迹分析占比 | D6: 整体指标 | E6: % | F6: CAR-010 ÷ CAR-011 × 100 | G6: ① 输入项 | H6: 分母 | I6: CAR-011 | J6: 主要产品类别总数 | K6: 原子参数 | L6: 个 | M6: 碳排放数据 | N6: — | O6: — | P6: ERP 系统 | Q6: 系统对接 | R6: 各项目公司 | S6: 指标直接输入项。单位全部主要产品类别数量
A7: 4 | B7: IND-003 | C7: 综合能源消费量 | D7: 整体指标 | E7: tce | F7: Σ( EN-015 × EN-016 ) ÷ 1000 | G7: ① 输入项 | H7: 维度 | I7: EN-014 | J7: 消耗的能源种类数 | K7: 原子参数 | L7: 个 | M7: 统计维度 | N7: — | O7: — | P7: 集控中心 | Q7: 计算 | R7: 电装 | S7: 指标直接输入项。参与综合能源消费量折算的能源品种数量
A8: 5 | B8: IND-003 | C8: 综合能源消费量 | D8: 整体指标 | E8: tce | F8: Σ( EN-015 × EN-016 ) ÷ 1000 | G8: ① 输入项 | H8: 因子 | I8: EN-015 | J8: 第 i 种能源消费量 | K8: 原子参数 | L8: 各品种原单位 | M8: 能源数据 | N8: — | O8: — | P8: 集控中心 | Q8: 自动采集 + 手工录入 | R8: 各项目公司 | S8: 指标直接输入项。参与折算的第 i 种能源实物消费量（电、天然气、蒸汽、热力、柴油、汽油、煤油等）
A9: 6 | B9: IND-003 | C9: 综合能源消费量 | D9: 整体指标 | E9: tce | F9: Σ( EN-015 × EN-016 ) ÷ 1000 | G9: ① 输入项 | H9: 系数 | I9: EN-016 | J9: 第 i 种能源折标准煤系数 | K9: 原子参数 | L9: kgce/单位或 tce/单位 | M9: 计算系数 | N9: — | O9: — | P9: 电装统一维护 | Q9: 系统维护 | R9: 电装 | S9: 指标直接输入项。第 i 种能源折算为标准煤的系数，由电装统一维护
A10: 7 | B10: IND-004 | C10: 总碳排放量 | D10: 整体指标 | E10: tCO2 | F10: ( CAR-002 + CAR-003 + CAR-004 + CAR-006 ) − ( CAR-005 + CAR-007 + CAR-008 ) | G10: ① 输入项 | H10: 加项 | I10: CAR-002 | J10: 化石燃料燃烧排放量 | K10: 原子参数 | L10: tCO2 | M10: 碳排放数据 | N10: — | O10: — | P10: 集控中心 | Q10: 计算 | R10: 电装 | S10: 指标直接输入项。化石燃料燃烧产生的二氧化碳排放量总和
A11: 8 | B11: IND-004 | C11: 总碳排放量 | D11: 整体指标 | E11: tCO2 | F11: ( CAR-002 + CAR-003 + CAR-004 + CAR-006 ) − ( CAR-005 + CAR-007 + CAR-008 ) | G11: ① 输入项 | H11: 加项 | I11: CAR-003 | J11: 过程排放量 | K11: 原子参数 | L11: tCO2 | M11: 碳排放数据 | N11: — | O11: — | P11: 集控中心 | Q11: 计算 | R11: 电装 | S11: 指标直接输入项。工业生产过程产生的二氧化碳排放量总和
A12: 9 | B12: IND-004 | C12: 总碳排放量 | D12: 整体指标 | E12: tCO2 | F12: ( CAR-002 + CAR-003 + CAR-004 + CAR-006 ) − ( CAR-005 + CAR-007 + CAR-008 ) | G12: ① 输入项 | H12: 加项 | I12: CAR-004 | J12: 购入电力排放量 | K12: 原子参数 | L12: tCO2 | M12: 碳排放数据 | N12: — | O12: — | P12: 集控中心 | Q12: 计算 | R12: 电装 | S12: 指标直接输入项。购入电力对应的二氧化碳排放量
A13: 10 | B13: IND-004 | C13: 总碳排放量 | D13: 整体指标 | E13: tCO2 | F13: ( CAR-002 + CAR-003 + CAR-004 + CAR-006 ) − ( CAR-005 + CAR-007 + CAR-008 ) | G13: ① 输入项 | H13: 扣减项 | I13: CAR-005 | J13: 输出电力排放量 | K13: 原子参数 | L13: tCO2 | M13: 碳排放数据 | N13: — | O13: — | P13: 集控中心 | Q13: 计算 | R13: 电装 | S13: 指标直接输入项。输出电力对应的二氧化碳排放量（扣减项）
A14: 11 | B14: IND-004 | C14: 总碳排放量 | D14: 整体指标 | E14: tCO2 | F14: ( CAR-002 + CAR-003 + CAR-004 + CAR-006 ) − ( CAR-005 + CAR-007 + CAR-008 ) | G14: ① 输入项 | H14: 加项 | I14: CAR-006 | J14: 购入热力排放量 | K14: 原子参数 | L14: tCO2 | M14: 碳排放数据 | N14: — | O14: — | P14: 集控中心 | Q14: 计算 | R14: 电装 | S14: 指标直接输入项。购入热力对应的二氧化碳排放量
A15: 12 | B15: IND-004 | C15: 总碳排放量 | D15: 整体指标 | E15: tCO2 | F15: ( CAR-002 + CAR-003 + CAR-004 + CAR-006 ) − ( CAR-005 + CAR-007 + CAR-008 ) | G15: ① 输入项 | H15: 扣减项 | I15: CAR-007 | J15: 输出热力排放量 | K15: 原子参数 | L15: tCO2 | M15: 碳排放数据 | N15: — | O15: — | P15: 集控中心 | Q15: 计算 | R15: 电装 | S15: 指标直接输入项。输出热力对应的二氧化碳排放量（扣减项）
... A217: 214 | B217: IND-094 | C217: 单位产量电耗（硅钢铁心-大型叠装） | D217: 关键工序 | E217: kWh/t | F217: EN-KE39 ÷ OUT-KM20 | G217: ① 输入项 | H217: 分母 | I217: OUT-KM20 | J217: 工序产品产量（硅钢铁心-大型叠装） | K217: 原子参数 | L217: t | M217: 产量数据 | N217: 硅钢铁心 | O217: 大型叠装 | P217: ERP / MES 生产工单与入库记录 | Q217: 系统接口 | R217: 各项目公司生产管理岗 | S217: 指标直接输入项。硅钢铁心大型叠装工序产品产量。
A219: 附 · 源表未单列的能源品种分项（待项目公司确认，共 11 项）
A220: IND-038 | C220: 单位产量能耗（变压器-特高压-试验） | E220: 工序综合能源消费量（变压器-特高压-试验）（EN-KT03） | G220: 综合能耗（EN-KT03）与电力消费量（EN-KE16）为两个独立变量，说明本工序还存在非电能源品种，但源表未单列。 | M220: 请项目公司确认该工序是否有蒸汽 / 天然气 / 热力计量点；如有，须补充对应参数编码后并入综合能耗折标计算。
A221: IND-043 | C221: 单位产量能耗（变压器-超高压-试验） | E221: 工序综合能源消费量（变压器-超高压-试验）（EN-KT05） | G221: 综合能耗（EN-KT05）与电力消费量（EN-KE18）为两个独立变量，说明本工序还存在非电能源品种，但源表未单列。 | M221: 请项目公司确认该工序是否有蒸汽 / 天然气 / 热力计量点；如有，须补充对应参数编码后并入综合能耗折标计算。
A222: IND-048 | C222: 单位产量能耗（变压器-高压-试验） | E222: 工序综合能源消费量（变压器-高压-试验）（EN-KT15） | G222: 综合能耗（EN-KT15）与电力消费量（EN-KE28）为两个独立变量，说明本工序还存在非电能源品种，但源表未单列。 | M222: 请项目公司确认该工序是否有蒸汽 / 天然气 / 热力计量点；如有，须补充对应参数编码后并入综合能耗折标计算。
A223: IND-050 | C223: 单位产量能耗（变压器-配变箱变-器身干燥） | E223: 工序综合能源消费量（变压器-配变箱变-器身干燥）（EN-KT12） | G223: 综合能耗（EN-KT12）与电力消费量（EN-KE25）为两个独立变量，说明本工序还存在非电能源品种，但源表未单列。 | M223: 请项目公司确认该工序是否有蒸汽 / 天然气 / 热力计量点；如有，须补充对应参数编码后并入综合能耗折标计算。
A224: IND-052 | C224: 单位产量能耗（变压器-配变箱变-试验） | E224: 工序综合能源消费量（变压器-配变箱变-试验）（EN-KT13） | G224: 综合能耗（EN-KT13）与电力消费量（EN-KE26）为两个独立变量，说明本工序还存在非电能源品种，但源表未单列。 | M224: 请项目公司确认该工序是否有蒸汽 / 天然气 / 热力计量点；如有，须补充对应参数编码后并入综合能耗折标计算。
A225: IND-054 | C225: 单位产量能耗（变压器-配变中特-器身干燥） | E225: 工序综合能源消费量（变压器-配变中特-器身干燥）（EN-KT06） | G225: 综合能耗（EN-KT06）与电力消费量（EN-KE19）为两个独立变量，说明本工序还存在非电能源品种，但源表未单列。 | M225: 请项目公司确认该工序是否有蒸汽 / 天然气 / 热力计量点；如有，须补充对应参数编码后并入综合能耗折标计算。
A226: IND-056 | C226: 单位产量能耗（变压器-配变中特-试验） | E226: 工序综合能源消费量（变压器-配变中特-试验）（EN-KT07） | G226: 综合能耗（EN-KT07）与电力消费量（EN-KE20）为两个独立变量，说明本工序还存在非电能源品种，但源表未单列。 | M226: 请项目公司确认该工序是否有蒸汽 / 天然气 / 热力计量点；如有，须补充对应参数编码后并入综合能耗折标计算。
A227: IND-058 | C227: 单位产量能耗（变压器-配变油变-器身干燥） | E227: 工序综合能源消费量（变压器-配变油变-器身干燥）（EN-KT10） | G227: 综合能耗（EN-KT10）与电力消费量（EN-KE23）为两个独立变量，说明本工序还存在非电能源品种，但源表未单列。 | M227: 请项目公司确认该工序是否有蒸汽 / 天然气 / 热力计量点；如有，须补充对应参数编码后并入综合能耗折标计算。
A228: IND-060 | C228: 单位产量能耗（变压器-配变油变-试验） | E228: 工序综合能源消费量（变压器-配变油变-试验）（EN-KT11） | G228: 综合能耗（EN-KT11）与电力消费量（EN-KE24）为两个独立变量，说明本工序还存在非电能源品种，但源表未单列。 | M228: 请项目公司确认该工序是否有蒸汽 / 天然气 / 热力计量点；如有，须补充对应参数编码后并入综合能耗折标计算。
A229: IND-062 | C229: 单位产量能耗（变压器-配变干变-浇注固化） | E229: 工序综合能源消费量（变压器-配变干变-浇注固化）（EN-KT08） | G229: 综合能耗（EN-KT08）与电力消费量（EN-KE21）为两个独立变量，说明本工序还存在非电能源品种，但源表未单列。 | M229: 请项目公司确认该工序是否有蒸汽 / 天然气 / 热力计量点；如有，须补充对应参数编码后并入综合能耗折标计算。
A230: IND-064 | C230: 单位产量能耗（变压器-配变干变-试验） | E230: 工序综合能源消费量（变压器-配变干变-试验）（EN-KT09） | G230: 综合能耗（EN-KT09）与电力消费量（EN-KE22）为两个独立变量，说明本工序还存在非电能源品种，但源表未单列。 | M230: 请项目公司确认该工序是否有蒸汽 / 天然气 / 热力计量点；如有，须补充对应参数编码后并入综合能耗折标计算。
